Workbook
Name 참고: #REF!
Name 참고: #REF!
Name 참고2: #REF!
Name 참조: #REF!
Name 참조: #REF!
Name 참조10: #REF!
Name 참조2: #REF!
Name 참조3: #REF!
Name 참조4: #REF!
Name 참코: #REF!

Sheet 기준
B2: 퇴근시간 | C2: 연장시간 | D2: 출근시간 | E2: 연장시간 | F2: 연장시간 | G2: 퇴근시간
B3: 0.35416667 | C3: -8 | D3: 0.35416667 | E3: =C3+8 -> 0 | F3: -8 | G3: 0.35416667
B4: 0.375 | C4: -7.5 | D4: 0.375 | E4: =C4+8 -> 0.5 | F4: -7.5 | G4: 0.375
B5: 0.39583333 | C5: -7 | D5: 0.39583333 | E5: =C5+8 -> 1 | F5: -7 | G5: 0.39583333
B6: 0.41666667 | C6: -6.5 | D6: 0.41666667 | E6: =C6+8 -> 1.5 | F6: -6.5 | G6: 0.41666667
B7: 0.4375 | C7: -6 | D7: 0.4375 | E7: =C7+8 -> 2 | F7: -6 | G7: 0.4375
B8: 0.45833333 | C8: -5.5 | D8: 0.45833333 | E8: =C8+8 -> 2.5 | F8: -5.5 | G8: 0.45833333
B9: 0.47916667 | C9: -5 | D9: 0.47916667 | E9: =C9+8 -> 3 | F9: -5 | G9: 0.47916667
B10: 0.5 | C10: -4.5 | D10: 0.5 | E10: =C10+8 -> 3.5 | F10: -4.5 | G10: 0.5
B11: 0.52083333 | C11: -4 | D11: 0.52083333 | E11: =C11+8 -> 4 | F11: -4 | G11: 0.52083333
B12: 0.54166667 | C12: -4 | D12: 0.54166667 | E12: =C12+8 -> 4 | F12: -4 | G12: 0.54166667
B13: 0.5625 | C13: -4 | D13: 0.5625 | E13: =C13+8 -> 4 | F13: -4 | G13: 0.5625
B14: 0.58333333 | C14: -3.5 | D14: 0.58333333 | E14: =C14+8 -> 4.5 | F14: -3.5 | G14: 0.58333333
... B50: 0.33333333 | C50: 13.5 | D50: 0.33333333 | E50: =C50+8 -> 21.5 | F50: 13.5 | G50: 0.33333333
C100: 구분
C101: 평일
C102: 주말

Sheet 공휴일
B2: 연장근무표_AF사업부
B3: 46083 | F3: 주말
B4: No | C4: 팀 | D4: 이름 | E4: 직위 | F4: 형태 | G4: 연장 근무 확정 | N4: =B3-1 -> 46082 | O4: 연장 근무 신청 | R4: =B3 -> 46083 | S4: 잔여 시간 | U4: 작성 확인
G5: 신청 | I5: 실제 | L5: 정상출근 기준 퇴근시간 | M5: 승인 | N5: 업무내용 | O5: 담당자 신청 | Q5: 승인 | R5: 업무내용
G6: 퇴근 | I6: 출근 | J6: 퇴근 | O6: 퇴근 | P6: 신청 | U6: 출/퇴근시간 | V6: 인원수
B7: =+ROW()-6 -> 1 | C7: 개발1팀 | D7: 임형준 | E7: 팀장 | F7: 정규 | G7: 0.72916667 | I7: 0.35416667 | J7: 0.72916667 | K7: =IFERROR(VLOOKUP(J7,기준!B:C,2,FALSE),"")-IFERROR(VLOOKUP(I7,기준!D:E,2,FALSE),"") -> 0 | L7: =IFERROR(VLOOKUP(K7,기준!F:G,2,FALSE),"") -> 0.72916667 | M7: =K7 -> 0 | N7: 휴무 | O7: 0.72916667 | Q7: 0 | R7: 휴무 | S7: 휴무 | U7: 0.35416667 | V7: =COUNTIF($I$7:$I$19,U7) -> 13
B8: =+ROW()-6 -> 2 | C8: 개발2팀 | D8: 박정환 | E8: 팀원 | F8: 정규 | G8: 0.72916667 | I8: 0.35416667 | J8: 0.72916667 | K8: =IFERROR(VLOOKUP(J8,기준!B:C,2,FALSE),"")-IFERROR(VLOOKUP(I8,기준!D:E,2,FALSE),"") -> 0 | L8: =IFERROR(VLOOKUP(K8,기준!F:G,2,FALSE),"") -> 0.72916667 | M8: =K8 -> 0 | N8: 휴무 | O8: 0.72916667 | Q8: 0 | R8: 휴무 | S8: 휴무 | U8: 0.39583333 | V8: =COUNTIF($I$7:$I$19,U8) -> 0
B9: =+ROW()-6 -> 3 | C9: 개발1팀 | D9: 박정찬 | E9: 팀원 | F9: 정규 | G9: 0.72916667 | I9: 0.35416667 | J9: 0.72916667 | K9: =IFERROR(VLOOKUP(J9,기준!B:C,2,FALSE),"")-IFERROR(VLOOKUP(I9,기준!D:E,2,FALSE),"") -> 0 | L9: =IFERROR(VLOOKUP(K9,기준!F:G,2,FALSE),"") -> 0.72916667 | M9: =K9 -> 0 | N9: 휴무 | O9: 0.72916667 | Q9: 0 | R9: 휴무 | S9: VINA 출장 | U9: 0.41666667 | V9: =COUNTIF($I$7:$I$19,U9) -> 0
B10: =+ROW()-6 -> 4 | C10: 개발1팀 | D10: 박태준 | E10: 팀원 | F10: 정규 | G10: 0.72916667 | I10: 0.35416667 | J10: 0.72916667 | K10: =IFERROR(VLOOKUP(J10,기준!B:C,2,FALSE),"")-IFERROR(VLOOKUP(I10,기준!D:E,2,FALSE),"") -> 0 | L10: =IFERROR(VLOOKUP(K10,기준!F:G,2,FALSE),"") -> 0.72916667 | M10: =K10 -> 0 | N10: 휴무 | O10: 0.72916667 | Q10: 0 | R10: 휴무 | U10: 0.5625 | V10: =COUNTIF($I$7:$I$19,U10) -> 0
B11: =+ROW()-6 -> 5 | C11: 개발1팀 | D11: 이형석 | E11: 팀원 | F11: 정규 | G11: 0.72916667 | I11: 0.35416667 | J11: 0.72916667 | K11: =IFERROR(VLOOKUP(J11,기준!B:C,2,FALSE),"")-IFERROR(VLOOKUP(I11,기준!D:E,2,FALSE),"") -> 0 | L11: =IFERROR(VLOOKUP(K11,기준!F:G,2,FALSE),"") -> 0.72916667 | M11: =K11 -> 0 | N11: 휴무 | O11: 0.72916667 | Q11: 0 | R11: 휴무 | U11: 0.72916667 | V11: =COUNTIF($J$7:$J$19,U11) -> 13
B12: =+ROW()-6 -> 6 | C12: 개발1팀 | D12: 김준영 | E12: 팀원 | F12: 정규 | G12: 0.72916667 | I12: 0.35416667 | J12: 0.72916667 | K12: =IFERROR(VLOOKUP(J12,기준!B:C,2,FALSE),"")-IFERROR(VLOOKUP(I12,기준!D:E,2,FALSE),"") -> 0 | L12: =IFERROR(VLOOKUP(K12,기준!F:G,2,FALSE),"") -> 0.72916667 | M12: =K12 -> 0 | N12: 휴무 | O12: 0.72916667 | Q12: 0 | R12: 휴무 | U12: 0.75 | V12: =COUNTIF($J$7:$J$19,U12) -> 0
B13: =+ROW()-6 -> 7 | C13: 개발1팀 | D13: 성민혁 | E13: 팀원 | F13: 정규 | G13: 0.72916667 | I13: 0.35416667 | J13: 0.72916667 | K13: =IFERROR(VLOOKUP(J13,기준!B:C,2,FALSE),"")-IFERROR(VLOOKUP(I13,기준!D:E,2,FALSE),"") -> 0 | L13: =IFERROR(VLOOKUP(K13,기준!F:G,2,FALSE),"") -> 0.72916667 | M13: =K13 -> 0 | N13: 휴무 | O13: 0.72916667 | Q13: 0 | R13: 휴무 | U13: 0.77083333 | V13: =COUNTIF($J$7:$J$19,U13) -> 0
B14: =+ROW()-6 -> 8 | C14: 개발1팀 | D14: 김남훈 | E14: 팀원 | F14: 정규 | G14: 0.72916667 | I14: 0.35416667 | J14: 0.72916667 | K14: =IFERROR(VLOOKUP(J14,기준!B:C,2,FALSE),"")-IFERROR(VLOOKUP(I14,기준!D:E,2,FALSE),"") -> 0 | L14: =IFERROR(VLOOKUP(K14,기준!F:G,2,FALSE),"") -> 0.72916667 | M14: =K14 -> 0 | N14: 휴무 | O14: 0.72916667 | Q14: 0 | R14: 휴무 | U14: 0.79166667 | V14: =COUNTIF($J$7:$J$19,U14) -> 0
B15: =+ROW()-6 -> 9 | C15: 개발2팀 | D15: 이종훈 | E15: 팀원 | F15: 정규 | G15: 0.72916667 | I15: 0.35416667 | J15: 0.72916667 | K15: =IFERROR(VLOOKUP(J15,기준!B:C,2,FALSE),"")-IFERROR(VLOOKUP(I15,기준!D:E,2,FALSE),"") -> 0 | L15: =IFERROR(VLOOKUP(K15,기준!F:G,2,FALSE),"") -> 0.72916667 | M15: =K15 -> 0 | N15: 휴무 | O15: 0.72916667 | Q15: 0 | R15: 휴무
B16: =+ROW()-6 -> 10 | C16: 개발3팀 | D16: 강한울 | E16: 파트장 | F16: 정규 | G16: 0.72916667 | I16: 0.35416667 | J16: 0.72916667 | K16: =IFERROR(VLOOKUP(J16,기준!B:C,2,FALSE),"")-IFERROR(VLOOKUP(I16,기준!D:E,2,FALSE),"") -> 0 | L16: =IFERROR(VLOOKUP(K16,기준!F:G,2,FALSE),"") -> 0.72916667 | M16: =K16 -> 0 | N16: 휴무 | O16: 0.72916667 | Q16: 0 | R16: 휴무 | S16: 휴무 | U16: 0.8125 | V16: =COUNTIF($J$7:$J$19,U16) -> 0
B17: =+ROW()-6 -> 11 | C17: 개발1팀 | D17: 김연호 | E17: 파트장 | F17: 정규 | G17: 0.72916667 | I17: 0.35416667 | J17: 0.72916667 | K17: =IFERROR(VLOOKUP(J17,기준!B:C,2,FALSE),"")-IFERROR(VLOOKUP(I17,기준!D:E,2,FALSE),"") -> 0 | L17: =IFERROR(VLOOKUP(K17,기준!F:G,2,FALSE),"") -> 0.72916667 | M17: =K17 -> 0 | N17: 휴무 | O17: 0.72916667 | Q17: 0 | R17: 휴무 | S17: VINA 출장 | U17: 0.83333333 | V17: =COUNTIF($J$7:$J$19,U17) -> 0
B18: =+ROW()-6 -> 12 | C18: 제어파트 | D18: 김동련 | E18: 팀원 | F18: 정규 | G18: 0.72916667 | I18: 0.35416667 | J18: 0.72916667 | K18: =IFERROR(VLOOKUP(J18,기준!B:C,2,FALSE),"")-IFERROR(VLOOKUP(I18,기준!D:E,2,FALSE),"") -> 0 | L18: =IFERROR(VLOOKUP(K18,기준!F:G,2,FALSE),"") -> 0.72916667 | M18: =K18 -> 0 | N18: 휴무 | O18: 0.72916667 | Q18: 0 | R18: 휴무 | U18: 0.875 | V18: =COUNTIF($J$7:$J$19,U18) -> 0
B19: =+ROW()-6 -> 13 | C19: 제어파트 | D19: 심효정 | E19: 팀원 | F19: 정규 | G19: 0.72916667 | I19: 0.35416667 | J19: 0.72916667 | K19: =IFERROR(VLOOKUP(J19,기준!B:C,2,FALSE),"")-IFERROR(VLOOKUP(I19,기준!D:E,2,FALSE),"") -> 0 | L19: =IFERROR(VLOOKUP(K19,기준!F:G,2,FALSE),"") -> 0.72916667 | M19: =K19 -> 0 | N19: 휴무 | O19: 0.72916667 | Q19: 0 | R19: 휴무 | U19: 0.89583333 | V19: =COUNTIF($J$7:$J$19,U19) -> 0
B20: =+ROW()-6 -> 14 | C20: 제어파트 | D20: 심효정 | E20: 팀원 | F20: 정규 | G20: 0.72916667 | I20: 0.35416667 | J20: 0.72916667 | K20: =IFERROR(VLOOKUP(J20,기준!B:C,2,FALSE),"")-IFERROR(VLOOKUP(I20,기준!D:E,2,FALSE),"") -> 0 | L20: =IFERROR(VLOOKUP(K20,기준!F:G,2,FALSE),"") -> 0.72916667 | M20: =K20 -> 0 | N20: 휴무 | O20: 0.72916667 | Q20: 0 | R20: 휴무 | U20: 1 | V20: =COUNTIF($J$7:$J$19,U20) -> 0
B21: =+ROW()-6 -> 15 | C21: 제어파트 | D21: 심효정 | E21: 팀원 | F21: 정규 | G21: 0.72916667 | I21: 0.35416667 | J21: 0.72916667 | K21: =IFERROR(VLOOKUP(J21,기준!B:C,2,FALSE),"")-IFERROR(VLOOKUP(I21,기준!D:E,2,FALSE),"") -> 0 | L21: =IFERROR(VLOOKUP(K21,기준!F:G,2,FALSE),"") -> 0.72916667 | M21: =K21 -> 0 | N21: 휴무 | O21: 0.72916667 | Q21: 0 | R21: 휴무 | U21: 1.0208333 | V21: =COUNTIF($J$7:$J$19,U21) -> 0
B22: =+ROW()-6 -> 16 | C22: 제어파트 | D22: 심효정 | E22: 팀원 | F22: 정규 | G22: 0.72916667 | I22: 0.35416667 | J22: 0.72916667 | K22: =IFERROR(VLOOKUP(J22,기준!B:C,2,FALSE),"")-IFERROR(VLOOKUP(I22,기준!D:E,2,FALSE),"") -> 0 | L22: =IFERROR(VLOOKUP(K22,기준!F:G,2,FALSE),"") -> 0.72916667 | M22: =K22 -> 0 | N22: 휴무 | O22: 0.72916667 | Q22: 0 | R22: 휴무 | U22: 1.0416667 | V22: =COUNTIF($J$7:$J$19,U22) -> 0
B23: =+ROW()-6 -> 17 | C23: 제어파트 | D23: 심효정 | E23: 팀원 | F23: 정규 | G23: 0.72916667 | I23: 0.35416667 | J23: 0.72916667 | K23: =IFERROR(VLOOKUP(J23,기준!B:C,2,FALSE),"")-IFERROR(VLOOKUP(I23,기준!D:E,2,FALSE),"") -> 0 | L23: =IFERROR(VLOOKUP(K23,기준!F:G,2,FALSE),"") -> 0.72916667 | M23: =K23 -> 0 | N23: 휴무 | O23: 0.72916667 | Q23: 0 | R23: 휴무 | U23: 1.0625 | V23: =COUNTIF($J$7:$J$19,U23) -> 0
B24: =+ROW()-6 -> 18 | C24: 제어파트 | D24: 심효정 | E24: 팀원 | F24: 정규 | G24: 0.72916667 | I24: 0.35416667 | J24: 0.72916667 | K24: =IFERROR(VLOOKUP(J24,기준!B:C,2,FALSE),"")-IFERROR(VLOOKUP(I24,기준!D:E,2,FALSE),"") -> 0 | L24: =IFERROR(VLOOKUP(K24,기준!F:G,2,FALSE),"") -> 0.72916667 | M24: =K24 -> 0 | N24: 휴무 | O24: 0.72916667 | Q24: 0 | R24: 휴무 | U24: 1.0833333 | V24: =COUNTIF($J$7:$J$19,U24) -> 0
B25: =+ROW()-6 -> 19 | C25: 제어파트 | D25: 심효정 | E25: 팀원 | F25: 정규 | G25: 0.72916667 | I25: 0.35416667 | J25: 0.72916667 | K25: =IFERROR(VLOOKUP(J25,기준!B:C,2,FALSE),"")-IFERROR(VLOOKUP(I25,기준!D:E,2,FALSE),"") -> 0 | L25: =IFERROR(VLOOKUP(K25,기준!F:G,2,FALSE),"") -> 0.72916667 | M25: =K25 -> 0 | N25: 휴무 | O25: 0.72916667 | Q25: 0 | R25: 휴무
B26: =+ROW()-6 -> 20 | C26: 제어파트 | D26: 심효정 | E26: 팀원 | F26: 정규 | G26: 0.72916667 | I26: 0.35416667 | J26: 0.72916667 | K26: =IFERROR(VLOOKUP(J26,기준!B:C,2,FALSE),"")-IFERROR(VLOOKUP(I26,기준!D:E,2,FALSE),"") -> 0 | L26: =IFERROR(VLOOKUP(K26,기준!F:G,2,FALSE),"") -> 0.72916667 | M26: =K26 -> 0 | N26: 휴무 | O26: 0.72916667 | Q26: 0 | R26: 휴무
B27: =+ROW()-6 -> 21 | C27: 제어파트 | D27: 심효정 | E27: 팀원 | F27: 정규 | G27: 0.72916667 | I27: 0.35416667 | J27: 0.72916667 | K27: =IFERROR(VLOOKUP(J27,기준!B:C,2,FALSE),"")-IFERROR(VLOOKUP(I27,기준!D:E,2,FALSE),"") -> 0 | L27: =IFERROR(VLOOKUP(K27,기준!F:G,2,FALSE),"") -> 0.72916667 | M27: =K27 -> 0 | N27: 휴무 | O27: 0.72916667 | Q27: 0 | R27: 휴무
B28: =+ROW()-6 -> 22 | C28: 제어파트 | D28: 심효정 | E28: 팀원 | F28: 정규 | G28: 0.72916667 | I28: 0.35416667 | J28: 0.72916667 | K28: =IFERROR(VLOOKUP(J28,기준!B:C,2,FALSE),"")-IFERROR(VLOOKUP(I28,기준!D:E,2,FALSE),"") -> 0 | L28: =IFERROR(VLOOKUP(K28,기준!F:G,2,FALSE),"") -> 0.72916667 | M28: =K28 -> 0 | N28: 휴무 | O28: 0.72916667 | Q28: 0 | R28: 휴무
B29: =+ROW()-6 -> 23 | C29: 제어파트 | D29: 심효정 | E29: 팀원 | F29: 정규 | G29: 0.72916667 | I29: 0.35416667 | J29: 0.72916667 | K29: =IFERROR(VLOOKUP(J29,기준!B:C,2,FALSE),"")-IFERROR(VLOOKUP(I29,기준!D:E,2,FALSE),"") -> 0 | L29: =IFERROR(VLOOKUP(K29,기준!F:G,2,FALSE),"") -> 0.72916667 | M29: =K29 -> 0 | N29: 휴무 | O29: 0.72916667 | Q29: 0 | R29: 휴무
B30: =+ROW()-6 -> 24 | C30: 제어파트 | D30: 심효정 | E30: 팀원 | F30: 정규 | G30: 0.72916667 | I30: 0.35416667 | J30: 0.72916667 | K30: =IFERROR(VLOOKUP(J30,기준!B:C,2,FALSE),"")-IFERROR(VLOOKUP(I30,기준!D:E,2,FALSE),"") -> 0 | L30: =IFERROR(VLOOKUP(K30,기준!F:G,2,FALSE),"") -> 0.72916667 | M30: =K30 -> 0 | N30: 휴무 | O30: 0.72916667 | Q30: 0 | R30: 휴무
B31: =+ROW()-6 -> 25 | C31: 제어파트 | D31: 심효정 | E31: 팀원 | F31: 정규 | G31: 0.72916667 | I31: 0.35416667 | J31: 0.72916667 | K31: =IFERROR(VLOOKUP(J31,기준!B:C,2,FALSE),"")-IFERROR(VLOOKUP(I31,기준!D:E,2,FALSE),"") -> 0 | L31: =IFERROR(VLOOKUP(K31,기준!F:G,2,FALSE),"") -> 0.72916667 | M31: =K31 -> 0 | N31: 휴무 | O31: 0.72916667 | Q31: 0 | R31: 휴무
B32: =+ROW()-6 -> 26 | C32: 제어파트 | D32: 심효정 | E32: 팀원 | F32: 정규 | G32: 0.72916667 | I32: 0.35416667 | J32: 0.72916667 | K32: =IFERROR(VLOOKUP(J32,기준!B:C,2,FALSE),"")-IFERROR(VLOOKUP(I32,기준!D:E,2,FALSE),"") -> 0 | L32: =IFERROR(VLOOKUP(K32,기준!F:G,2,FALSE),"") -> 0.72916667 | M32: =K32 -> 0 | N32: 휴무 | O32: 0.72916667 | Q32: 0 | R32: 휴무
B33: =+ROW()-6 -> 27 | C33: 제어파트 | D33: 심효정 | E33: 팀원 | F33: 정규 | G33: 0.72916667 | I33: 0.35416667 | J33: 0.72916667 | K33: =IFERROR(VLOOKUP(J33,기준!B:C,2,FALSE),"")-IFERROR(VLOOKUP(I33,기준!D:E,2,FALSE),"") -> 0 | L33: =IFERROR(VLOOKUP(K33,기준!F:G,2,FALSE),"") -> 0.72916667 | M33: =K33 -> 0 | N33: 휴무 | O33: 0.72916667 | Q33: 0 | R33: 휴무
B34: =+ROW()-6 -> 28 | C34: 제어파트 | D34: 심효정 | E34: 팀원 | F34: 정규 | G34: 0.72916667 | I34: 0.35416667 | J34: 0.72916667 | K34: =IFERROR(VLOOKUP(J34,기준!B:C,2,FALSE),"")-IFERROR(VLOOKUP(I34,기준!D:E,2,FALSE),"") -> 0 | L34: =IFERROR(VLOOKUP(K34,기준!F:G,2,FALSE),"") -> 0.72916667 | M34: =K34 -> 0 | N34: 휴무 | O34: 0.72916667 | Q34: 0 | R34: 휴무
B35: =+ROW()-6 -> 29 | C35: 제어파트 | D35: 심효정 | E35: 팀원 | F35: 정규 | G35: 0.72916667 | I35: 0.35416667 | J35: 0.72916667 | K35: =IFERROR(VLOOKUP(J35,기준!B:C,2,FALSE),"")-IFERROR(VLOOKUP(I35,기준!D:E,2,FALSE),"") -> 0 | L35: =IFERROR(VLOOKUP(K35,기준!F:G,2,FALSE),"") -> 0.72916667 | M35: =K35 -> 0 | N35: 휴무 | O35: 0.72916667 | Q35: 0 | R35: 휴무
B36: =+ROW()-6 -> 30 | C36: 제어파트 | D36: 심효정 | E36: 팀원 | F36: 정규 | G36: 0.72916667 | I36: 0.35416667 | J36: 0.72916667 | K36: =IFERROR(VLOOKUP(J36,기준!B:C,2,FALSE),"")-IFERROR(VLOOKUP(I36,기준!D:E,2,FALSE),"") -> 0 | L36: =IFERROR(VLOOKUP(K36,기준!F:G,2,FALSE),"") -> 0.72916667 | M36: =K36 -> 0 | N36: 휴무 | O36: 0.72916667 | Q36: 0 | R36: 휴무
... B40: =+ROW()-6 -> 34 | C40: 제어파트 | D40: 심효정 | E40: 팀원 | F40: 정규 | G40: 0.72916667 | I40: 0.35416667 | J40: 0.72916667 | K40: =IFERROR(VLOOKUP(J40,기준!B:C,2,FALSE),"")-IFERROR(VLOOKUP(I40,기준!D:E,2,FALSE),"") -> 0 | L40: =IFERROR(VLOOKUP(K40,기준!F:G,2,FALSE),"") -> 0.72916667 | M40: =K40 -> 0 | N40: 휴무 | O40: 0.72916667 | Q40: 0 | R40: 휴무
Q43: `

Sheet 토요일
B2: 연장근무표_AF사업부
B3: 46102 | F3: 주말
B4: No | C4: 팀 | D4: 이름 | E4: 직위 | F4: 형태 | G4: 연장 근무 확정 | N4: =B3-1 -> 46101 | O4: 연장 근무 신청 | R4: =B3 -> 46102 | S4: 잔여 시간 | U4: 작성 확인
G5: 신청 | I5: 실제 | L5: 정상출근 기준 퇴근시간 | M5: 승인 | N5: 업무내용 | O5: 담당자 신청 | Q5: 승인 | R5: 업무내용
G6: 퇴근 | I6: 출근 | J6: 퇴근 | O6: 퇴근 | P6: 신청 | U6: 출/퇴근시간 | V6: 인원수
B7: =+ROW()-6 -> 1 | C7: 개발1팀 | D7: 임형준 | E7: 팀장 | F7: 정규 | G7: 0.72916667 | I7: 0.35416667 | J7: 0.72916667 | K7: =IFERROR(VLOOKUP(J7,[1]기준!B:C,2,FALSE),"")-IFERROR(VLOOKUP(I7,[1]기준!D:E,2,FALSE),"") -> 0 | L7: =IFERROR(VLOOKUP(K7,[1]기준!F:G,2,FALSE),"") -> 0.72916667 | M7: =K7 -> 0 | N7: 신규 모델 관련 업무 진행 | O7: 0.72916667 | Q7: 0 | R7: 휴무 | S7: 휴무 | U7: 0.35416667 | V7: =COUNTIF($I$7:$I$19,U7) -> 13
B8: =+ROW()-6 -> 2 | C8: 개발2팀 | D8: 박정환 | E8: 팀원 | F8: 정규 | G8: 0.72916667 | I8: 0.35416667 | J8: 0.72916667 | K8: =IFERROR(VLOOKUP(J8,[1]기준!B:C,2,FALSE),"")-IFERROR(VLOOKUP(I8,[1]기준!D:E,2,FALSE),"") -> 0 | L8: =IFERROR(VLOOKUP(K8,[1]기준!F:G,2,FALSE),"") -> 0.72916667 | M8: =K8 -> 0 | N8: 신규 모델 관련 업무 진행 | O8: 0.72916667 | Q8: 0 | R8: 휴무 | S8: 휴무 | U8: 0.39583333 | V8: =COUNTIF($I$7:$I$19,U8) -> 0
B9: =+ROW()-6 -> 3 | C9: 개발1팀 | D9: 박정찬 | E9: 팀원 | F9: 정규 | G9: 0.72916667 | I9: 0.35416667 | J9: 0.72916667 | K9: =IFERROR(VLOOKUP(J9,[1]기준!B:C,2,FALSE),"")-IFERROR(VLOOKUP(I9,[1]기준!D:E,2,FALSE),"") -> 0 | L9: =IFERROR(VLOOKUP(K9,[1]기준!F:G,2,FALSE),"") -> 0.72916667 | M9: =K9 -> 0 | N9: 신규 모델 관련 업무 진행 | O9: 0.72916667 | Q9: 0 | R9: 휴무 | S9: VINA 출장 | U9: 0.41666667 | V9: =COUNTIF($I$7:$I$19,U9) -> 0
B10: =+ROW()-6 -> 4 | C10: 개발1팀 | D10: 박태준 | E10: 팀원 | F10: 정규 | G10: 0.72916667 | I10: 0.35416667 | J10: 0.72916667 | K10: =IFERROR(VLOOKUP(J10,[1]기준!B:C,2,FALSE),"")-IFERROR(VLOOKUP(I10,[1]기준!D:E,2,FALSE),"") -> 0 | L10: =IFERROR(VLOOKUP(K10,[1]기준!F:G,2,FALSE),"") -> 0.72916667 | M10: =K10 -> 0 | N10: 신규 모델 관련 업무 진행 | O10: 0.72916667 | Q10: 0 | R10: 휴무 | U10: 0.5625 | V10: =COUNTIF($I$7:$I$19,U10) -> 0
B11: =+ROW()-6 -> 5 | C11: 개발1팀 | D11: 이형석 | E11: 팀원 | F11: 정규 | G11: 0.72916667 | I11: 0.35416667 | J11: 0.72916667 | K11: =IFERROR(VLOOKUP(J11,[1]기준!B:C,2,FALSE),"")-IFERROR(VLOOKUP(I11,[1]기준!D:E,2,FALSE),"") -> 0 | L11: =IFERROR(VLOOKUP(K11,[1]기준!F:G,2,FALSE),"") -> 0.72916667 | M11: =K11 -> 0 | N11: 신규 모델 관련 업무 진행 | O11: 0.72916667 | Q11: 0 | R11: 휴무 | U11: 0.72916667 | V11: =COUNTIF($J$7:$J$19,U11) -> 13
B12: =+ROW()-6 -> 6 | C12: 개발1팀 | D12: 김준영 | E12: 팀원 | F12: 정규 | G12: 0.72916667 | I12: 0.35416667 | J12: 0.72916667 | K12: =IFERROR(VLOOKUP(J12,[1]기준!B:C,2,FALSE),"")-IFERROR(VLOOKUP(I12,[1]기준!D:E,2,FALSE),"") -> 0 | L12: =IFERROR(VLOOKUP(K12,[1]기준!F:G,2,FALSE),"") -> 0.72916667 | M12: =K12 -> 0 | N12: 신규 모델 관련 업무 진행 | O12: 0.72916667 | Q12: 0 | R12: 휴무 | U12: 0.75 | V12: =COUNTIF($J$7:$J$19,U12) -> 0
B13: =+ROW()-6 -> 7 | C13: 개발1팀 | D13: 성민혁 | E13: 팀원 | F13: 정규 | G13: 0.72916667 | I13: 0.35416667 | J13: 0.72916667 | K13: =IFERROR(VLOOKUP(J13,[1]기준!B:C,2,FALSE),"")-IFERROR(VLOOKUP(I13,[1]기준!D:E,2,FALSE),"") -> 0 | L13: =IFERROR(VLOOKUP(K13,[1]기준!F:G,2,FALSE),"") -> 0.72916667 | M13: =K13 -> 0 | N13: 신규 모델 관련 업무 진행 | O13: 0.72916667 | Q13: 0 | R13: 휴무 | U13: 0.77083333 | V13: =COUNTIF($J$7:$J$19,U13) -> 0
B14: =+ROW()-6 -> 8 | C14: 개발1팀 | D14: 김남훈 | E14: 팀원 | F14: 정규 | G14: 0.72916667 | I14: 0.35416667 | J14: 0.72916667 | K14: =IFERROR(VLOOKUP(J14,[1]기준!B:C,2,FALSE),"")-IFERROR(VLOOKUP(I14,[1]기준!D:E,2,FALSE),"") -> 0 | L14: =IFERROR(VLOOKUP(K14,[1]기준!F:G,2,FALSE),"") -> 0.72916667 | M14: =K14 -> 0 | N14: 신규 모델 관련 업무 진행 | O14: 0.72916667 | Q14: 0 | R14: 휴무 | U14: 0.79166667 | V14: =COUNTIF($J$7:$J$19,U14) -> 0
B15: =+ROW()-6 -> 9 | C15: 개발2팀 | D15: 이종훈 | E15: 팀원 | F15: 정규 | G15: 0.72916667 | I15: 0.35416667 | J15: 0.72916667 | K15: =IFERROR(VLOOKUP(J15,[1]기준!B:C,2,FALSE),"")-IFERROR(VLOOKUP(I15,[1]기준!D:E,2,FALSE),"") -> 0 | L15: =IFERROR(VLOOKUP(K15,[1]기준!F:G,2,FALSE),"") -> 0.72916667 | M15: =K15 -> 0 | N15: 신규 모델 관련 업무 진행 | O15: 0.72916667 | Q15: 0 | R15: 휴무
B16: =+ROW()-6 -> 10 | C16: 개발3팀 | D16: 강한울 | E16: 파트장 | F16: 정규 | G16: 0.72916667 | I16: 0.35416667 | J16: 0.72916667 | K16: =IFERROR(VLOOKUP(J16,[1]기준!B:C,2,FALSE),"")-IFERROR(VLOOKUP(I16,[1]기준!D:E,2,FALSE),"") -> 0 | L16: =IFERROR(VLOOKUP(K16,[1]기준!F:G,2,FALSE),"") -> 0.72916667 | M16: =K16 -> 0 | N16: 신규 모델 관련 업무 진행 | O16: 0.72916667 | Q16: 0 | R16: 휴무 | S16: 휴무 | U16: 0.8125 | V16: =COUNTIF($J$7:$J$19,U16) -> 0
B17: =+ROW()-6 -> 11 | C17: 개발1팀 | D17: 김연호 | E17: 파트장 | F17: 정규 | G17: 0.72916667 | I17: 0.35416667 | J17: 0.72916667 | K17: =IFERROR(VLOOKUP(J17,[1]기준!B:C,2,FALSE),"")-IFERROR(VLOOKUP(I17,[1]기준!D:E,2,FALSE),"") -> 0 | L17: =IFERROR(VLOOKUP(K17,[1]기준!F:G,2,FALSE),"") -> 0.72916667 | M17: =K17 -> 0 | N17: 신규 모델 관련 업무 진행 | O17: 0.72916667 | Q17: 0 | R17: 휴무 | S17: VINA 출장 | U17: 0.83333333 | V17: =COUNTIF($J$7:$J$19,U17) -> 0
B18: =+ROW()-6 -> 12 | C18: 제어파트 | D18: 김동련 | E18: 팀원 | F18: 정규 | G18: 0.72916667 | I18: 0.35416667 | J18: 0.72916667 | K18: =IFERROR(VLOOKUP(J18,[1]기준!B:C,2,FALSE),"")-IFERROR(VLOOKUP(I18,[1]기준!D:E,2,FALSE),"") -> 0 | L18: =IFERROR(VLOOKUP(K18,[1]기준!F:G,2,FALSE),"") -> 0.72916667 | M18: =K18 -> 0 | N18: 신규 모델 관련 업무 진행 | O18: 0.72916667 | Q18: 0 | R18: 휴무 | U18: 0.875 | V18: =COUNTIF($J$7:$J$19,U18) -> 0
B19: =+ROW()-6 -> 13 | C19: 제어파트 | D19: 심효정 | E19: 팀원 | F19: 정규 | G19: 0.72916667 | I19: 0.35416667 | J19: 0.72916667 | K19: =IFERROR(VLOOKUP(J19,[1]기준!B:C,2,FALSE),"")-IFERROR(VLOOKUP(I19,[1]기준!D:E,2,FALSE),"") -> 0 | L19: =IFERROR(VLOOKUP(K19,[1]기준!F:G,2,FALSE),"") -> 0.72916667 | M19: =K19 -> 0 | N19: 신규 모델 관련 업무 진행 | O19: 0.72916667 | Q19: 0 | R19: 휴무 | U19: 0.89583333 | V19: =COUNTIF($J$7:$J$19,U19) -> 0
B20: =+ROW()-6 -> 14 | C20: 개발1팀 | D20: 김연호 | E20: 파트장 | F20: 정규 | G20: 0.72916667 | I20: 0.35416667 | J20: 0.72916667 | K20: =IFERROR(VLOOKUP(J20,기준!B:C,2,FALSE),"")-IFERROR(VLOOKUP(I20,기준!D:E,2,FALSE),"") -> 0 | L20: =IFERROR(VLOOKUP(K20,기준!F:G,2,FALSE),"") -> 0.72916667 | M20: =K20 -> 0 | N20: 신규 모델 관련 업무 진행 | O20: 0.72916667 | Q20: 0 | R20: 휴무 | U20: 1 | V20: =COUNTIF($J$7:$J$19,U20) -> 0
B21: =+ROW()-6 -> 15 | C21: 제어파트 | D21: 김동련 | E21: 팀원 | F21: 정규 | G21: 0.72916667 | I21: 0.35416667 | J21: 0.72916667 | K21: =IFERROR(VLOOKUP(J21,기준!B:C,2,FALSE),"")-IFERROR(VLOOKUP(I21,기준!D:E,2,FALSE),"") -> 0 | L21: =IFERROR(VLOOKUP(K21,기준!F:G,2,FALSE),"") -> 0.72916667 | M21: =K21 -> 0 | N21: 신규 모델 관련 업무 진행 | O21: 0.72916667 | Q21: 0 | R21: 휴무 | U21: 1.0208333 | V21: =COUNTIF($J$7:$J$19,U21) -> 0
B22: =+ROW()-6 -> 16 | C22: 제어파트 | D22: 심효정 | E22: 팀원 | F22: 정규 | G22: 0.72916667 | I22: 0.35416667 | J22: 0.72916667 | K22: =IFERROR(VLOOKUP(J22,기준!B:C,2,FALSE),"")-IFERROR(VLOOKUP(I22,기준!D:E,2,FALSE),"") -> 0 | L22: =IFERROR(VLOOKUP(K22,기준!F:G,2,FALSE),"") -> 0.72916667 | M22: =K22 -> 0 | N22: 신규 모델 관련 업무 진행 | O22: 0.72916667 | Q22: 0 | R22: 휴무 | U22: 1.0416667 | V22: =COUNTIF($J$7:$J$19,U22) -> 0
B23: =+ROW()-6 -> 17 | C23: 제어파트 | D23: 심효정 | E23: 팀원 | F23: 정규 | G23: 0.72916667 | I23: 0.35416667 | J23: 0.72916667 | K23: =IFERROR(VLOOKUP(J23,기준!B:C,2,FALSE),"")-IFERROR(VLOOKUP(I23,기준!D:E,2,FALSE),"") -> 0 | L23: =IFERROR(VLOOKUP(K23,기준!F:G,2,FALSE),"") -> 0.72916667 | M23: =K23 -> 0 | N23: 신규 모델 관련 업무 진행 | O23: 0.72916667 | Q23: 0 | R23: 휴무 | U23: 1.0625 | V23: =COUNTIF($J$7:$J$19,U23) -> 0
B24: =+ROW()-6 -> 18 | C24: 제어파트 | D24: 심효정 | E24: 팀원 | F24: 정규 | G24: 0.72916667 | I24: 0.35416667 | J24: 0.72916667 | K24: =IFERROR(VLOOKUP(J24,기준!B:C,2,FALSE),"")-IFERROR(VLOOKUP(I24,기준!D:E,2,FALSE),"") -> 0 | L24: =IFERROR(VLOOKUP(K24,기준!F:G,2,FALSE),"") -> 0.72916667 | M24: =K24 -> 0 | N24: 신규 모델 관련 업무 진행 | O24: 0.72916667 | Q24: 0 | R24: 휴무 | U24: 1.0833333 | V24: =COUNTIF($J$7:$J$19,U24) -> 0
B25: =+ROW()-6 -> 19 | C25: 제어파트 | D25: 심효정 | E25: 팀원 | F25: 정규 | G25: 0.72916667 | I25: 0.35416667 | J25: 0.72916667 | K25: =IFERROR(VLOOKUP(J25,기준!B:C,2,FALSE),"")-IFERROR(VLOOKUP(I25,기준!D:E,2,FALSE),"") -> 0 | L25: =IFERROR(VLOOKUP(K25,기준!F:G,2,FALSE),"") -> 0.72916667 | M25: =K25 -> 0 | N25: 신규 모델 관련 업무 진행 | O25: 0.72916667 | Q25: 0 | R25: 휴무
B26: =+ROW()-6 -> 20 | C26: 제어파트 | D26: 심효정 | E26: 팀원 | F26: 정규 | G26: 0.72916667 | I26: 0.35416667 | J26: 0.72916667 | K26: =IFERROR(VLOOKUP(J26,기준!B:C,2,FALSE),"")-IFERROR(VLOOKUP(I26,기준!D:E,2,FALSE),"") -> 0 | L26: =IFERROR(VLOOKUP(K26,기준!F:G,2,FALSE),"") -> 0.72916667 | M26: =K26 -> 0 | N26: 신규 모델 관련 업무 진행 | O26: 0.72916667 | Q26: 0 | R26: 휴무
B27: =+ROW()-6 -> 21 | C27: 제어파트 | D27: 심효정 | E27: 팀원 | F27: 정규 | G27: 0.72916667 | I27: 0.35416667 | J27: 0.72916667 | K27: =IFERROR(VLOOKUP(J27,기준!B:C,2,FALSE),"")-IFERROR(VLOOKUP(I27,기준!D:E,2,FALSE),"") -> 0 | L27: =IFERROR(VLOOKUP(K27,기준!F:G,2,FALSE),"") -> 0.72916667 | M27: =K27 -> 0 | N27: 신규 모델 관련 업무 진행 | O27: 0.72916667 | Q27: 0 | R27: 휴무
B28: =+ROW()-6 -> 22 | C28: 제어파트 | D28: 심효정 | E28: 팀원 | F28: 정규 | G28: 0.72916667 | I28: 0.35416667 | J28: 0.72916667 | K28: =IFERROR(VLOOKUP(J28,기준!B:C,2,FALSE),"")-IFERROR(VLOOKUP(I28,기준!D:E,2,FALSE),"") -> 0 | L28: =IFERROR(VLOOKUP(K28,기준!F:G,2,FALSE),"") -> 0.72916667 | M28: =K28 -> 0 | N28: 신규 모델 관련 업무 진행 | O28: 0.72916667 | Q28: 0 | R28: 휴무
B29: =+ROW()-6 -> 23 | C29: 제어파트 | D29: 심효정 | E29: 팀원 | F29: 정규 | G29: 0.72916667 | I29: 0.35416667 | J29: 0.72916667 | K29: =IFERROR(VLOOKUP(J29,기준!B:C,2,FALSE),"")-IFERROR(VLOOKUP(I29,기준!D:E,2,FALSE),"") -> 0 | L29: =IFERROR(VLOOKUP(K29,기준!F:G,2,FALSE),"") -> 0.72916667 | M29: =K29 -> 0 | N29: 신규 모델 관련 업무 진행 | O29: 0.72916667 | Q29: 0 | R29: 휴무
B30: =+ROW()-6 -> 24 | C30: 제어파트 | D30: 심효정 | E30: 팀원 | F30: 정규 | G30: 0.72916667 | I30: 0.35416667 | J30: 0.72916667 | K30: =IFERROR(VLOOKUP(J30,기준!B:C,2,FALSE),"")-IFERROR(VLOOKUP(I30,기준!D:E,2,FALSE),"") -> 0 | L30: =IFERROR(VLOOKUP(K30,기준!F:G,2,FALSE),"") -> 0.72916667 | M30: =K30 -> 0 | N30: 신규 모델 관련 업무 진행 | O30: 0.72916667 | Q30: 0 | R30: 휴무
B31: =+ROW()-6 -> 25 | C31: 제어파트 | D31: 심효정 | E31: 팀원 | F31: 정규 | G31: 0.72916667 | I31: 0.35416667 | J31: 0.72916667 | K31: =IFERROR(VLOOKUP(J31,기준!B:C,2,FALSE),"")-IFERROR(VLOOKUP(I31,기준!D:E,2,FALSE),"") -> 0 | L31: =IFERROR(VLOOKUP(K31,기준!F:G,2,FALSE),"") -> 0.72916667 | M31: =K31 -> 0 | N31: 신규 모델 관련 업무 진행 | O31: 0.72916667 | Q31: 0 | R31: 휴무
B32: =+ROW()-6 -> 26 | C32: 제어파트 | D32: 심효정 | E32: 팀원 | F32: 정규 | G32: 0.72916667 | I32: 0.35416667 | J32: 0.72916667 | K32: =IFERROR(VLOOKUP(J32,기준!B:C,2,FALSE),"")-IFERROR(VLOOKUP(I32,기준!D:E,2,FALSE),"") -> 0 | L32: =IFERROR(VLOOKUP(K32,기준!F:G,2,FALSE),"") -> 0.72916667 | M32: =K32 -> 0 | N32: 신규 모델 관련 업무 진행 | O32: 0.72916667 | Q32: 0 | R32: 휴무
B33: =+ROW()-6 -> 27 | C33: 제어파트 | D33: 심효정 | E33: 팀원 | F33: 정규 | G33: 0.72916667 | I33: 0.35416667 | J33: 0.72916667 | K33: =IFERROR(VLOOKUP(J33,기준!B:C,2,FALSE),"")-IFERROR(VLOOKUP(I33,기준!D:E,2,FALSE),"") -> 0 | L33: =IFERROR(VLOOKUP(K33,기준!F:G,2,FALSE),"") -> 0.72916667 | M33: =K33 -> 0 | N33: 신규 모델 관련 업무 진행 | O33: 0.72916667 | Q33: 0 | R33: 휴무
B34: =+ROW()-6 -> 28 | C34: 제어파트 | D34: 심효정 | E34: 팀원 | F34: 정규 | G34: 0.72916667 | I34: 0.35416667 | J34: 0.72916667 | K34: =IFERROR(VLOOKUP(J34,기준!B:C,2,FALSE),"")-IFERROR(VLOOKUP(I34,기준!D:E,2,FALSE),"") -> 0 | L34: =IFERROR(VLOOKUP(K34,기준!F:G,2,FALSE),"") -> 0.72916667 | M34: =K34 -> 0 | N34: 신규 모델 관련 업무 진행 | O34: 0.72916667 | Q34: 0 | R34: 휴무
B35: =+ROW()-6 -> 29 | C35: 제어파트 | D35: 심효정 | E35: 팀원 | F35: 정규 | G35: 0.72916667 | I35: 0.35416667 | J35: 0.72916667 | K35: =IFERROR(VLOOKUP(J35,기준!B:C,2,FALSE),"")-IFERROR(VLOOKUP(I35,기준!D:E,2,FALSE),"") -> 0 | L35: =IFERROR(VLOOKUP(K35,기준!F:G,2,FALSE),"") -> 0.72916667 | M35: =K35 -> 0 | N35: 신규 모델 관련 업무 진행 | O35: 0.72916667 | Q35: 0 | R35: 휴무
B36: =+ROW()-6 -> 30 | C36: 제어파트 | D36: 심효정 | E36: 팀원 | F36: 정규 | G36: 0.72916667 | I36: 0.35416667 | J36: 0.72916667 | K36: =IFERROR(VLOOKUP(J36,기준!B:C,2,FALSE),"")-IFERROR(VLOOKUP(I36,기준!D:E,2,FALSE),"") -> 0 | L36: =IFERROR(VLOOKUP(K36,기준!F:G,2,FALSE),"") -> 0.72916667 | M36: =K36 -> 0 | N36: 신규 모델 관련 업무 진행 | O36: 0.72916667 | Q36: 0 | R36: 휴무
... B43: =+ROW()-6 -> 37 | C43: 제어파트 | D43: 심효정 | E43: 팀원 | F43: 정규 | G43: 0.72916667 | I43: 0.35416667 | J43: 0.72916667 | K43: =IFERROR(VLOOKUP(J43,기준!B:C,2,FALSE),"")-IFERROR(VLOOKUP(I43,기준!D:E,2,FALSE),"") -> 0 | L43: =IFERROR(VLOOKUP(K43,기준!F:G,2,FALSE),"") -> 0.72916667 | M43: =K43 -> 0 | N43: 신규 모델 관련 업무 진행 | O43: 0.72916667 | Q43: 0 | R43: 휴무

Sheet 일요일
B2: 연장근무표_AF사업부
B3: 46103 | F3: 주말
B4: No | C4: 팀 | D4: 이름 | E4: 직위 | F4: 형태 | G4: 연장 근무 확정 | N4: =B3-1 -> 46102 | O4: 연장 근무 신청 | R4: =B3 -> 46103 | S4: 잔여 시간 | U4: 작성 확인
G5: 신청 | I5: 실제 | L5: 정상출근 기준 퇴근시간 | M5: 승인 | N5: 업무내용 | O5: 담당자 신청 | Q5: 승인 | R5: 업무내용
G6: 퇴근 | I6: 출근 | J6: 퇴근 | O6: 퇴근 | P6: 신청 | U6: 출/퇴근시간 | V6: 인원수
B7: =+ROW()-6 -> 1 | C7: 개발1팀 | D7: 임형준 | E7: 팀장 | F7: 정규 | G7: 0.72916667 | I7: 0.35416667 | J7: 0.72916667 | K7: =IFERROR(VLOOKUP(J7,[1]기준!B:C,2,FALSE),"")-IFERROR(VLOOKUP(I7,[1]기준!D:E,2,FALSE),"") -> 0 | L7: =IFERROR(VLOOKUP(K7,[1]기준!F:G,2,FALSE),"") -> 0.72916667 | M7: =K7 -> 0 | N7: 휴무 | O7: 0.72916667 | Q7: 0 | R7: 휴무 | S7: 휴무 | U7: 0.35416667 | V7: =COUNTIF($I$7:$I$19,U7) -> 13
B8: =+ROW()-6 -> 2 | C8: 개발2팀 | D8: 박정환 | E8: 팀원 | F8: 정규 | G8: 0.72916667 | I8: 0.35416667 | J8: 0.72916667 | K8: =IFERROR(VLOOKUP(J8,[1]기준!B:C,2,FALSE),"")-IFERROR(VLOOKUP(I8,[1]기준!D:E,2,FALSE),"") -> 0 | L8: =IFERROR(VLOOKUP(K8,[1]기준!F:G,2,FALSE),"") -> 0.72916667 | M8: =K8 -> 0 | N8: 휴무 | O8: 0.72916667 | Q8: 0 | R8: 휴무 | S8: 휴무 | U8: 0.39583333 | V8: =COUNTIF($I$7:$I$19,U8) -> 0
B9: =+ROW()-6 -> 3 | C9: 개발1팀 | D9: 박정찬 | E9: 팀원 | F9: 정규 | G9: 0.72916667 | I9: 0.35416667 | J9: 0.72916667 | K9: =IFERROR(VLOOKUP(J9,[1]기준!B:C,2,FALSE),"")-IFERROR(VLOOKUP(I9,[1]기준!D:E,2,FALSE),"") -> 0 | L9: =IFERROR(VLOOKUP(K9,[1]기준!F:G,2,FALSE),"") -> 0.72916667 | M9: =K9 -> 0 | N9: 휴무 | O9: 0.72916667 | Q9: 0 | R9: 휴무 | S9: VINA 출장 | U9: 0.41666667 | V9: =COUNTIF($I$7:$I$19,U9) -> 0
B10: =+ROW()-6 -> 4 | C10: 개발1팀 | D10: 박태준 | E10: 팀원 | F10: 정규 | G10: 0.72916667 | I10: 0.35416667 | J10: 0.72916667 | K10: =IFERROR(VLOOKUP(J10,[1]기준!B:C,2,FALSE),"")-IFERROR(VLOOKUP(I10,[1]기준!D:E,2,FALSE),"") -> 0 | L10: =IFERROR(VLOOKUP(K10,[1]기준!F:G,2,FALSE),"") -> 0.72916667 | M10: =K10 -> 0 | N10: 휴무 | O10: 0.72916667 | Q10: 0 | R10: 휴무 | U10: 0.5625 | V10: =COUNTIF($I$7:$I$19,U10) -> 0
B11: =+ROW()-6 -> 5 | C11: 개발1팀 | D11: 이형석 | E11: 팀원 | F11: 정규 | G11: 0.72916667 | I11: 0.35416667 | J11: 0.72916667 | K11: =IFERROR(VLOOKUP(J11,[1]기준!B:C,2,FALSE),"")-IFERROR(VLOOKUP(I11,[1]기준!D:E,2,FALSE),"") -> 0 | L11: =IFERROR(VLOOKUP(K11,[1]기준!F:G,2,FALSE),"") -> 0.72916667 | M11: =K11 -> 0 | N11: 휴무 | O11: 0.72916667 | Q11: 0 | R11: 휴무 | U11: 0.72916667 | V11: =COUNTIF($J$7:$J$19,U11) -> 13
B12: =+ROW()-6 -> 6 | C12: 개발1팀 | D12: 김준영 | E12: 팀원 | F12: 정규 | G12: 0.72916667 | I12: 0.35416667 | J12: 0.72916667 | K12: =IFERROR(VLOOKUP(J12,[1]기준!B:C,2,FALSE),"")-IFERROR(VLOOKUP(I12,[1]기준!D:E,2,FALSE),"") -> 0 | L12: =IFERROR(VLOOKUP(K12,[1]기준!F:G,2,FALSE),"") -> 0.72916667 | M12: =K12 -> 0 | N12: 휴무 | O12: 0.72916667 | Q12: 0 | R12: 휴무 | U12: 0.75 | V12: =COUNTIF($J$7:$J$19,U12) -> 0
B13: =+ROW()-6 -> 7 | C13: 개발1팀 | D13: 성민혁 | E13: 팀원 | F13: 정규 | G13: 0.72916667 | I13: 0.35416667 | J13: 0.72916667 | K13: =IFERROR(VLOOKUP(J13,[1]기준!B:C,2,FALSE),"")-IFERROR(VLOOKUP(I13,[1]기준!D:E,2,FALSE),"") -> 0 | L13: =IFERROR(VLOOKUP(K13,[1]기준!F:G,2,FALSE),"") -> 0.72916667 | M13: =K13 -> 0 | N13: 휴무 | O13: 0.72916667 | Q13: 0 | R13: 휴무 | U13: 0.77083333 | V13: =COUNTIF($J$7:$J$19,U13) -> 0
B14: =+ROW()-6 -> 8 | C14: 개발1팀 | D14: 김남훈 | E14: 팀원 | F14: 정규 | G14: 0.72916667 | I14: 0.35416667 | J14: 0.72916667 | K14: =IFERROR(VLOOKUP(J14,[1]기준!B:C,2,FALSE),"")-IFERROR(VLOOKUP(I14,[1]기준!D:E,2,FALSE),"") -> 0 | L14: =IFERROR(VLOOKUP(K14,[1]기준!F:G,2,FALSE),"") -> 0.72916667 | M14: =K14 -> 0 | N14: 휴무 | O14: 0.72916667 | Q14: 0 | R14: 휴무 | U14: 0.79166667 | V14: =COUNTIF($J$7:$J$19,U14) -> 0
B15: =+ROW()-6 -> 9 | C15: 개발2팀 | D15: 이종훈 | E15: 팀원 | F15: 정규 | G15: 0.72916667 | I15: 0.35416667 | J15: 0.72916667 | K15: =IFERROR(VLOOKUP(J15,[1]기준!B:C,2,FALSE),"")-IFERROR(VLOOKUP(I15,[1]기준!D:E,2,FALSE),"") -> 0 | L15: =IFERROR(VLOOKUP(K15,[1]기준!F:G,2,FALSE),"") -> 0.72916667 | M15: =K15 -> 0 | N15: 휴무 | O15: 0.72916667 | Q15: 0 | R15: 휴무
B16: =+ROW()-6 -> 10 | C16: 개발3팀 | D16: 강한울 | E16: 파트장 | F16: 정규 | G16: 0.72916667 | I16: 0.35416667 | J16: 0.72916667 | K16: =IFERROR(VLOOKUP(J16,[1]기준!B:C,2,FALSE),"")-IFERROR(VLOOKUP(I16,[1]기준!D:E,2,FALSE),"") -> 0 | L16: =IFERROR(VLOOKUP(K16,[1]기준!F:G,2,FALSE),"") -> 0.72916667 | M16: =K16 -> 0 | N16: 휴무 | O16: 0.72916667 | Q16: 0 | R16: 휴무 | S16: 휴무 | U16: 0.8125 | V16: =COUNTIF($J$7:$J$19,U16) -> 0
B17: =+ROW()-6 -> 11 | C17: 개발1팀 | D17: 김연호 | E17: 파트장 | F17: 정규 | G17: 0.72916667 | I17: 0.35416667 | J17: 0.72916667 | K17: =IFERROR(VLOOKUP(J17,[1]기준!B:C,2,FALSE),"")-IFERROR(VLOOKUP(I17,[1]기준!D:E,2,FALSE),"") -> 0 | L17: =IFERROR(VLOOKUP(K17,[1]기준!F:G,2,FALSE),"") -> 0.72916667 | M17: =K17 -> 0 | N17: 휴무 | O17: 0.72916667 | Q17: 0 | R17: 휴무 | S17: VINA 출장 | U17: 0.83333333 | V17: =COUNTIF($J$7:$J$19,U17) -> 0
B18: =+ROW()-6 -> 12 | C18: 제어파트 | D18: 김동련 | E18: 팀원 | F18: 정규 | G18: 0.72916667 | I18: 0.35416667 | J18: 0.72916667 | K18: =IFERROR(VLOOKUP(J18,[1]기준!B:C,2,FALSE),"")-IFERROR(VLOOKUP(I18,[1]기준!D:E,2,FALSE),"") -> 0 | L18: =IFERROR(VLOOKUP(K18,[1]기준!F:G,2,FALSE),"") -> 0.72916667 | M18: =K18 -> 0 | N18: 휴무 | O18: 0.72916667 | Q18: 0 | R18: 휴무 | U18: 0.875 | V18: =COUNTIF($J$7:$J$19,U18) -> 0
B19: =+ROW()-6 -> 13 | C19: 제어파트 | D19: 심효정 | E19: 팀원 | F19: 정규 | G19: 0.72916667 | I19: 0.35416667 | J19: 0.72916667 | K19: =IFERROR(VLOOKUP(J19,[1]기준!B:C,2,FALSE),"")-IFERROR(VLOOKUP(I19,[1]기준!D:E,2,FALSE),"") -> 0 | L19: =IFERROR(VLOOKUP(K19,[1]기준!F:G,2,FALSE),"") -> 0.72916667 | M19: =K19 -> 0 | N19: 휴무 | O19: 0.72916667 | Q19: 0 | R19: 휴무 | U19: 0.89583333 | V19: =COUNTIF($J$7:$J$19,U19) -> 0
B20: =+ROW()-6 -> 14 | C20: 개발1팀 | D20: 김연호 | E20: 파트장 | F20: 정규 | G20: 0.72916667 | I20: 0.35416667 | J20: 0.72916667 | K20: =IFERROR(VLOOKUP(J20,기준!B:C,2,FALSE),"")-IFERROR(VLOOKUP(I20,기준!D:E,2,FALSE),"") -> 0 | L20: =IFERROR(VLOOKUP(K20,기준!F:G,2,FALSE),"") -> 0.72916667 | M20: =K20 -> 0 | N20: 휴무 | O20: 0.72916667 | Q20: 0 | R20: 휴무 | U20: 1 | V20: =COUNTIF($J$7:$J$19,U20) -> 0
B21: =+ROW()-6 -> 15 | C21: 제어파트 | D21: 김동련 | E21: 팀원 | F21: 정규 | G21: 0.72916667 | I21: 0.35416667 | J21: 0.72916667 | K21: =IFERROR(VLOOKUP(J21,기준!B:C,2,FALSE),"")-IFERROR(VLOOKUP(I21,기준!D:E,2,FALSE),"") -> 0 | L21: =IFERROR(VLOOKUP(K21,기준!F:G,2,FALSE),"") -> 0.72916667 | M21: =K21 -> 0 | N21: 휴무 | O21: 0.72916667 | Q21: 0 | R21: 휴무 | U21: 1.0208333 | V21: =COUNTIF($J$7:$J$19,U21) -> 0
B22: =+ROW()-6 -> 16 | C22: 제어파트 | D22: 심효정 | E22: 팀원 | F22: 정규 | G22: 0.72916667 | I22: 0.35416667 | J22: 0.72916667 | K22: =IFERROR(VLOOKUP(J22,기준!B:C,2,FALSE),"")-IFERROR(VLOOKUP(I22,기준!D:E,2,FALSE),"") -> 0 | L22: =IFERROR(VLOOKUP(K22,기준!F:G,2,FALSE),"") -> 0.72916667 | M22: =K22 -> 0 | N22: 휴무 | O22: 0.72916667 | Q22: 0 | R22: 휴무 | U22: 1.0416667 | V22: =COUNTIF($J$7:$J$19,U22) -> 0
B23: =+ROW()-6 -> 17 | C23: 제어파트 | D23: 심효정 | E23: 팀원 | F23: 정규 | G23: 0.72916667 | I23: 0.35416667 | J23: 0.72916667 | K23: =IFERROR(VLOOKUP(J23,기준!B:C,2,FALSE),"")-IFERROR(VLOOKUP(I23,기준!D:E,2,FALSE),"") -> 0 | L23: =IFERROR(VLOOKUP(K23,기준!F:G,2,FALSE),"") -> 0.72916667 | M23: =K23 -> 0 | N23: 휴무 | O23: 0.72916667 | Q23: 0 | R23: 휴무 | U23: 1.0625 | V23: =COUNTIF($J$7:$J$19,U23) -> 0
B24: =+ROW()-6 -> 18 | C24: 제어파트 | D24: 심효정 | E24: 팀원 | F24: 정규 | G24: 0.72916667 | I24: 0.35416667 | J24: 0.72916667 | K24: =IFERROR(VLOOKUP(J24,기준!B:C,2,FALSE),"")-IFERROR(VLOOKUP(I24,기준!D:E,2,FALSE),"") -> 0 | L24: =IFERROR(VLOOKUP(K24,기준!F:G,2,FALSE),"") -> 0.72916667 | M24: =K24 -> 0 | N24: 휴무 | O24: 0.72916667 | Q24: 0 | R24: 휴무 | U24: 1.0833333 | V24: =COUNTIF($J$7:$J$19,U24) -> 0
B25: =+ROW()-6 -> 19 | C25: 제어파트 | D25: 심효정 | E25: 팀원 | F25: 정규 | G25: 0.72916667 | I25: 0.35416667 | J25: 0.72916667 | K25: =IFERROR(VLOOKUP(J25,기준!B:C,2,FALSE),"")-IFERROR(VLOOKUP(I25,기준!D:E,2,FALSE),"") -> 0 | L25: =IFERROR(VLOOKUP(K25,기준!F:G,2,FALSE),"") -> 0.72916667 | M25: =K25 -> 0 | N25: 휴무 | O25: 0.72916667 | Q25: 0 | R25: 휴무
B26: =+ROW()-6 -> 20 | C26: 제어파트 | D26: 심효정 | E26: 팀원 | F26: 정규 | G26: 0.72916667 | I26: 0.35416667 | J26: 0.72916667 | K26: =IFERROR(VLOOKUP(J26,기준!B:C,2,FALSE),"")-IFERROR(VLOOKUP(I26,기준!D:E,2,FALSE),"") -> 0 | L26: =IFERROR(VLOOKUP(K26,기준!F:G,2,FALSE),"") -> 0.72916667 | M26: =K26 -> 0 | N26: 휴무 | O26: 0.72916667 | Q26: 0 | R26: 휴무
B27: =+ROW()-6 -> 21 | C27: 제어파트 | D27: 심효정 | E27: 팀원 | F27: 정규 | G27: 0.72916667 | I27: 0.35416667 | J27: 0.72916667 | K27: =IFERROR(VLOOKUP(J27,기준!B:C,2,FALSE),"")-IFERROR(VLOOKUP(I27,기준!D:E,2,FALSE),"") -> 0 | L27: =IFERROR(VLOOKUP(K27,기준!F:G,2,FALSE),"") -> 0.72916667 | M27: =K27 -> 0 | N27: 휴무 | O27: 0.72916667 | Q27: 0 | R27: 휴무
B28: =+ROW()-6 -> 22 | C28: 제어파트 | D28: 심효정 | E28: 팀원 | F28: 정규 | G28: 0.72916667 | I28: 0.35416667 | J28: 0.72916667 | K28: =IFERROR(VLOOKUP(J28,기준!B:C,2,FALSE),"")-IFERROR(VLOOKUP(I28,기준!D:E,2,FALSE),"") -> 0 | L28: =IFERROR(VLOOKUP(K28,기준!F:G,2,FALSE),"") -> 0.72916667 | M28: =K28 -> 0 | N28: 휴무 | O28: 0.72916667 | Q28: 0 | R28: 휴무
B29: =+ROW()-6 -> 23 | C29: 제어파트 | D29: 심효정 | E29: 팀원 | F29: 정규 | G29: 0.72916667 | I29: 0.35416667 | J29: 0.72916667 | K29: =IFERROR(VLOOKUP(J29,기준!B:C,2,FALSE),"")-IFERROR(VLOOKUP(I29,기준!D:E,2,FALSE),"") -> 0 | L29: =IFERROR(VLOOKUP(K29,기준!F:G,2,FALSE),"") -> 0.72916667 | M29: =K29 -> 0 | N29: 휴무 | O29: 0.72916667 | Q29: 0 | R29: 휴무
B30: =+ROW()-6 -> 24 | C30: 제어파트 | D30: 심효정 | E30: 팀원 | F30: 정규 | G30: 0.72916667 | I30: 0.35416667 | J30: 0.72916667 | K30: =IFERROR(VLOOKUP(J30,기준!B:C,2,FALSE),"")-IFERROR(VLOOKUP(I30,기준!D:E,2,FALSE),"") -> 0 | L30: =IFERROR(VLOOKUP(K30,기준!F:G,2,FALSE),"") -> 0.72916667 | M30: =K30 -> 0 | N30: 휴무 | O30: 0.72916667 | Q30: 0 | R30: 휴무
B31: =+ROW()-6 -> 25 | C31: 제어파트 | D31: 심효정 | E31: 팀원 | F31: 정규 | G31: 0.72916667 | I31: 0.35416667 | J31: 0.72916667 | K31: =IFERROR(VLOOKUP(J31,기준!B:C,2,FALSE),"")-IFERROR(VLOOKUP(I31,기준!D:E,2,FALSE),"") -> 0 | L31: =IFERROR(VLOOKUP(K31,기준!F:G,2,FALSE),"") -> 0.72916667 | M31: =K31 -> 0 | N31: 휴무 | O31: 0.72916667 | Q31: 0 | R31: 휴무
B32: =+ROW()-6 -> 26 | C32: 제어파트 | D32: 심효정 | E32: 팀원 | F32: 정규 | G32: 0.72916667 | I32: 0.35416667 | J32: 0.72916667 | K32: =IFERROR(VLOOKUP(J32,기준!B:C,2,FALSE),"")-IFERROR(VLOOKUP(I32,기준!D:E,2,FALSE),"") -> 0 | L32: =IFERROR(VLOOKUP(K32,기준!F:G,2,FALSE),"") -> 0.72916667 | M32: =K32 -> 0 | N32: 휴무 | O32: 0.72916667 | Q32: 0 | R32: 휴무
B33: =+ROW()-6 -> 27 | C33: 제어파트 | D33: 심효정 | E33: 팀원 | F33: 정규 | G33: 0.72916667 | I33: 0.35416667 | J33: 0.72916667 | K33: =IFERROR(VLOOKUP(J33,기준!B:C,2,FALSE),"")-IFERROR(VLOOKUP(I33,기준!D:E,2,FALSE),"") -> 0 | L33: =IFERROR(VLOOKUP(K33,기준!F:G,2,FALSE),"") -> 0.72916667 | M33: =K33 -> 0 | N33: 휴무 | O33: 0.72916667 | Q33: 0 | R33: 휴무
B34: =+ROW()-6 -> 28 | C34: 제어파트 | D34: 심효정 | E34: 팀원 | F34: 정규 | G34: 0.72916667 | I34: 0.35416667 | J34: 0.72916667 | K34: =IFERROR(VLOOKUP(J34,기준!B:C,2,FALSE),"")-IFERROR(VLOOKUP(I34,기준!D:E,2,FALSE),"") -> 0 | L34: =IFERROR(VLOOKUP(K34,기준!F:G,2,FALSE),"") -> 0.72916667 | M34: =K34 -> 0 | N34: 휴무 | O34: 0.72916667 | Q34: 0 | R34: 휴무
B35: =+ROW()-6 -> 29 | C35: 제어파트 | D35: 심효정 | E35: 팀원 | F35: 정규 | G35: 0.72916667 | I35: 0.35416667 | J35: 0.72916667 | K35: =IFERROR(VLOOKUP(J35,기준!B:C,2,FALSE),"")-IFERROR(VLOOKUP(I35,기준!D:E,2,FALSE),"") -> 0 | L35: =IFERROR(VLOOKUP(K35,기준!F:G,2,FALSE),"") -> 0.72916667 | M35: =K35 -> 0 | N35: 휴무 | O35: 0.72916667 | Q35: 0 | R35: 휴무
B36: =+ROW()-6 -> 30 | C36: 제어파트 | D36: 심효정 | E36: 팀원 | F36: 정규 | G36: 0.72916667 | I36: 0.35416667 | J36: 0.72916667 | K36: =IFERROR(VLOOKUP(J36,기준!B:C,2,FALSE),"")-IFERROR(VLOOKUP(I36,기준!D:E,2,FALSE),"") -> 0 | L36: =IFERROR(VLOOKUP(K36,기준!F:G,2,FALSE),"") -> 0.72916667 | M36: =K36 -> 0 | N36: 휴무 | O36: 0.72916667 | Q36: 0 | R36: 휴무
... B43: =+ROW()-6 -> 37 | C43: 제어파트 | D43: 심효정 | E43: 팀원 | F43: 정규 | G43: 0.72916667 | I43: 0.35416667 | J43: 0.72916667 | K43: =IFERROR(VLOOKUP(J43,기준!B:C,2,FALSE),"")-IFERROR(VLOOKUP(I43,기준!D:E,2,FALSE),"") -> 0 | L43: =IFERROR(VLOOKUP(K43,기준!F:G,2,FALSE),"") -> 0.72916667 | M43: =K43 -> 0 | N43: 휴무 | O43: 0.72916667 | Q43: 0 | R43: 휴무

Sheet 월요일
B2: 연장근무표_AF사업부
B3: 46104 | F3: 평일
B4: No | C4: 팀 | D4: 이름 | E4: 직위 | F4: 형태 | G4: 연장 근무 확정 | N4: =B3-1 -> 46103 | O4: 연장 근무 신청 | R4: =B3 -> 46104 | S4: 잔여 시간 | U4: 작성 확인
G5: 신청 | I5: 실제 | L5: 정상출근 기준 퇴근시간 | M5: 승인 | N5: 업무내용 | O5: 담당자 신청 | Q5: 승인 | R5: 업무내용
G6: 퇴근 | I6: 출근 | J6: 퇴근 | O6: 퇴근 | P6: 신청 | U6: 출/퇴근시간 | V6: 인원수
B7: =+ROW()-6 -> 1 | C7: 개발1팀 | D7: 임형준 | E7: 팀장 | F7: 정규 | G7: 0.72916667 | I7: 0.35416667 | J7: 0.72916667 | K7: =IF(OR(I7="",J7=""),0, IF(AND(HOUR(I7)=8,MINUTE(I7)=30), IF(IF(J7<I7,J7+1,J7)<TIME(18,0,0),0, IF(IF(J7<I7,J7+1,J7)<=TIME(19,30,0), ROUND((IF(J7<I7,J7+1,J7)-TIME(17,30,0))*24,1), ROUND((IF(J7<I7,J7+1,J7)-TIME(18,30,0))*24,1) ) ), IF(AND(HOUR(I7)=10,MINUTE(I7)=0), IF(IF(J7<I7,J7+1,J7)<=TIME(20,0,0),0, ROUND((IF(J7<I7,J7+1,J7)-TIME(20,0,0))*24,1) ), 0 ) )) -> 0 | L7: =IFERROR(VLOOKUP(K7,기준!F:G,2,FALSE),"") -> 0.72916667 | M7: =K7 -> 0 | N7: 휴무 | O7: 0.72916667 | Q7: 0 | R7: 신규 모델 관련 업무 진행 | S7: 휴무 | U7: 0.35416667 | V7: =COUNTIF($I$7:$I$19,U7) -> 13
B8: =+ROW()-6 -> 2 | C8: 개발2팀 | D8: 박정환 | E8: 팀원 | F8: 정규 | G8: 0.72916667 | I8: 0.35416667 | J8: 0.72916667 | K8: =IF(OR(I8="",J8=""),0, IF(AND(HOUR(I8)=8,MINUTE(I8)=30), IF(IF(J8<I8,J8+1,J8)<TIME(18,0,0),0, IF(IF(J8<I8,J8+1,J8)<=TIME(19,30,0), ROUND((IF(J8<I8,J8+1,J8)-TIME(17,30,0))*24,1), ROUND((IF(J8<I8,J8+1,J8)-TIME(18,30,0))*24,1) ) ), IF(AND(HOUR(I8)=10,MINUTE(I8)=0), IF(IF(J8<I8,J8+1,J8)<=TIME(20,0,0),0, ROUND((IF(J8<I8,J8+1,J8)-TIME(20,0,0))*24,1) ), 0 ) )) -> 0 | L8: =IFERROR(VLOOKUP(K8,기준!F:G,2,FALSE),"") -> 0.72916667 | M8: =K8 -> 0 | N8: 휴무 | O8: 0.72916667 | Q8: 0 | R8: 신규 모델 관련 업무 진행 | S8: 휴무 | U8: 0.39583333 | V8: =COUNTIF($I$7:$I$19,U8) -> 0
B9: =+ROW()-6 -> 3 | C9: 개발1팀 | D9: 박정찬 | E9: 팀원 | F9: 정규 | G9: 0.72916667 | I9: 0.35416667 | J9: 0.72916667 | K9: =IF(OR(I9="",J9=""),0, IF(AND(HOUR(I9)=8,MINUTE(I9)=30), IF(IF(J9<I9,J9+1,J9)<TIME(18,0,0),0, IF(IF(J9<I9,J9+1,J9)<=TIME(19,30,0), ROUND((IF(J9<I9,J9+1,J9)-TIME(17,30,0))*24,1), ROUND((IF(J9<I9,J9+1,J9)-TIME(18,30,0))*24,1) ) ), IF(AND(HOUR(I9)=10,MINUTE(I9)=0), IF(IF(J9<I9,J9+1,J9)<=TIME(20,0,0),0, ROUND((IF(J9<I9,J9+1,J9)-TIME(20,0,0))*24,1) ), 0 ) )) -> 0 | L9: =IFERROR(VLOOKUP(K9,기준!F:G,2,FALSE),"") -> 0.72916667 | M9: =K9 -> 0 | N9: 휴무 | O9: 0.72916667 | Q9: 0 | R9: 신규 모델 관련 업무 진행 | S9: VINA 출장 | U9: 0.41666667 | V9: =COUNTIF($I$7:$I$19,U9) -> 0
B10: =+ROW()-6 -> 4 | C10: 개발1팀 | D10: 박태준 | E10: 팀원 | F10: 정규 | G10: 0.72916667 | I10: 0.35416667 | J10: 0.72916667 | K10: =IF(OR(I10="",J10=""),0, IF(AND(HOUR(I10)=8,MINUTE(I10)=30), IF(IF(J10<I10,J10+1,J10)<TIME(18,0,0),0, IF(IF(J10<I10,J10+1,J10)<=TIME(19,30,0), ROUND((IF(J10<I10,J10+1,J10)-TIME(17,30,0))*24,1), ROUND((IF(J10<I10,J10+1,J10)-TIME(18,30,0))*24,1) ) ), IF(AND(HOUR(I10)=10,MINUTE(I10)=0), IF(IF(J10<I10,J10+1,J10)<=TIME(20,0,0),0, ROUND((IF(J10<I10,J10+1,J10)-TIME(20,0,0))*24,1) ), 0 ) )) -> 0 | L10: =IFERROR(VLOOKUP(K10,기준!F:G,2,FALSE),"") -> 0.72916667 | M10: =K10 -> 0 | N10: 휴무 | O10: 0.72916667 | Q10: 0 | R10: 신규 모델 관련 업무 진행 | U10: 0.5625 | V10: =COUNTIF($I$7:$I$19,U10) -> 0
B11: =+ROW()-6 -> 5 | C11: 개발1팀 | D11: 이형석 | E11: 팀원 | F11: 정규 | G11: 0.72916667 | I11: 0.35416667 | J11: 0.72916667 | K11: =IF(OR(I11="",J11=""),0, IF(AND(HOUR(I11)=8,MINUTE(I11)=30), IF(IF(J11<I11,J11+1,J11)<TIME(18,0,0),0, IF(IF(J11<I11,J11+1,J11)<=TIME(19,30,0), ROUND((IF(J11<I11,J11+1,J11)-TIME(17,30,0))*24,1), ROUND((IF(J11<I11,J11+1,J11)-TIME(18,30,0))*24,1) ) ), IF(AND(HOUR(I11)=10,MINUTE(I11)=0), IF(IF(J11<I11,J11+1,J11)<=TIME(20,0,0),0, ROUND((IF(J11<I11,J11+1,J11)-TIME(20,0,0))*24,1) ), 0 ) )) -> 0 | L11: =IFERROR(VLOOKUP(K11,기준!F:G,2,FALSE),"") -> 0.72916667 | M11: =K11 -> 0 | N11: 휴무 | O11: 0.72916667 | Q11: 0 | R11: 신규 모델 관련 업무 진행 | U11: 0.72916667 | V11: =COUNTIF($J$7:$J$19,U11) -> 13
B12: =+ROW()-6 -> 6 | C12: 개발1팀 | D12: 김준영 | E12: 팀원 | F12: 정규 | G12: 0.72916667 | I12: 0.35416667 | J12: 0.72916667 | K12: =IF(OR(I12="",J12=""),0, IF(AND(HOUR(I12)=8,MINUTE(I12)=30), IF(IF(J12<I12,J12+1,J12)<TIME(18,0,0),0, IF(IF(J12<I12,J12+1,J12)<=TIME(19,30,0), ROUND((IF(J12<I12,J12+1,J12)-TIME(17,30,0))*24,1), ROUND((IF(J12<I12,J12+1,J12)-TIME(18,30,0))*24,1) ) ), IF(AND(HOUR(I12)=10,MINUTE(I12)=0), IF(IF(J12<I12,J12+1,J12)<=TIME(20,0,0),0, ROUND((IF(J12<I12,J12+1,J12)-TIME(20,0,0))*24,1) ), 0 ) )) -> 0 | L12: =IFERROR(VLOOKUP(K12,기준!F:G,2,FALSE),"") -> 0.72916667 | M12: =K12 -> 0 | N12: 휴무 | O12: 0.72916667 | Q12: 0 | R12: 신규 모델 관련 업무 진행 | U12: 0.75 | V12: =COUNTIF($J$7:$J$19,U12) -> 0
B13: =+ROW()-6 -> 7 | C13: 개발1팀 | D13: 성민혁 | E13: 팀원 | F13: 정규 | G13: 0.72916667 | I13: 0.35416667 | J13: 0.72916667 | K13: =IF(OR(I13="",J13=""),0, IF(AND(HOUR(I13)=8,MINUTE(I13)=30), IF(IF(J13<I13,J13+1,J13)<TIME(18,0,0),0, IF(IF(J13<I13,J13+1,J13)<=TIME(19,30,0), ROUND((IF(J13<I13,J13+1,J13)-TIME(17,30,0))*24,1), ROUND((IF(J13<I13,J13+1,J13)-TIME(18,30,0))*24,1) ) ), IF(AND(HOUR(I13)=10,MINUTE(I13)=0), IF(IF(J13<I13,J13+1,J13)<=TIME(20,0,0),0, ROUND((IF(J13<I13,J13+1,J13)-TIME(20,0,0))*24,1) ), 0 ) )) -> 0 | L13: =IFERROR(VLOOKUP(K13,기준!F:G,2,FALSE),"") -> 0.72916667 | M13: =K13 -> 0 | N13: 휴무 | O13: 0.72916667 | Q13: 0 | R13: 신규 모델 관련 업무 진행 | U13: 0.77083333 | V13: =COUNTIF($J$7:$J$19,U13) -> 0
B14: =+ROW()-6 -> 8 | C14: 개발1팀 | D14: 김남훈 | E14: 팀원 | F14: 정규 | G14: 0.72916667 | I14: 0.35416667 | J14: 0.72916667 | K14: =IF(OR(I14="",J14=""),0, IF(AND(HOUR(I14)=8,MINUTE(I14)=30), IF(IF(J14<I14,J14+1,J14)<TIME(18,0,0),0, IF(IF(J14<I14,J14+1,J14)<=TIME(19,30,0), ROUND((IF(J14<I14,J14+1,J14)-TIME(17,30,0))*24,1), ROUND((IF(J14<I14,J14+1,J14)-TIME(18,30,0))*24,1) ) ), IF(AND(HOUR(I14)=10,MINUTE(I14)=0), IF(IF(J14<I14,J14+1,J14)<=TIME(20,0,0),0, ROUND((IF(J14<I14,J14+1,J14)-TIME(20,0,0))*24,1) ), 0 ) )) -> 0 | L14: =IFERROR(VLOOKUP(K14,기준!F:G,2,FALSE),"") -> 0.72916667 | M14: =K14 -> 0 | N14: 휴무 | O14: 0.72916667 | Q14: 0 | R14: 신규 모델 관련 업무 진행 | U14: 0.79166667 | V14: =COUNTIF($J$7:$J$19,U14) -> 0
B15: =+ROW()-6 -> 9 | C15: 개발2팀 | D15: 이종훈 | E15: 팀원 | F15: 정규 | G15: 0.72916667 | I15: 0.35416667 | J15: 0.72916667 | K15: =IF(OR(I15="",J15=""),0, IF(AND(HOUR(I15)=8,MINUTE(I15)=30), IF(IF(J15<I15,J15+1,J15)<TIME(18,0,0),0, IF(IF(J15<I15,J15+1,J15)<=TIME(19,30,0), ROUND((IF(J15<I15,J15+1,J15)-TIME(17,30,0))*24,1), ROUND((IF(J15<I15,J15+1,J15)-TIME(18,30,0))*24,1) ) ), IF(AND(HOUR(I15)=10,MINUTE(I15)=0), IF(IF(J15<I15,J15+1,J15)<=TIME(20,0,0),0, ROUND((IF(J15<I15,J15+1,J15)-TIME(20,0,0))*24,1) ), 0 ) )) -> 0 | L15: =IFERROR(VLOOKUP(K15,기준!F:G,2,FALSE),"") -> 0.72916667 | M15: =K15 -> 0 | N15: 휴무 | O15: 0.72916667 | Q15: 0 | R15: 신규 모델 관련 업무 진행
B16: =+ROW()-6 -> 10 | C16: 개발3팀 | D16: 강한울 | E16: 파트장 | F16: 정규 | G16: 0.72916667 | I16: 0.35416667 | J16: 0.72916667 | K16: =IF(OR(I16="",J16=""),0, IF(AND(HOUR(I16)=8,MINUTE(I16)=30), IF(IF(J16<I16,J16+1,J16)<TIME(18,0,0),0, IF(IF(J16<I16,J16+1,J16)<=TIME(19,30,0), ROUND((IF(J16<I16,J16+1,J16)-TIME(17,30,0))*24,1), ROUND((IF(J16<I16,J16+1,J16)-TIME(18,30,0))*24,1) ) ), IF(AND(HOUR(I16)=10,MINUTE(I16)=0), IF(IF(J16<I16,J16+1,J16)<=TIME(20,0,0),0, ROUND((IF(J16<I16,J16+1,J16)-TIME(20,0,0))*24,1) ), 0 ) )) -> 0 | L16: =IFERROR(VLOOKUP(K16,기준!F:G,2,FALSE),"") -> 0.72916667 | M16: =K16 -> 0 | N16: 휴무 | O16: 0.72916667 | Q16: 0 | R16: 신규 모델 관련 업무 진행 | S16: 휴무 | U16: 0.8125 | V16: =COUNTIF($J$7:$J$19,U16) -> 0
B17: =+ROW()-6 -> 11 | C17: 개발1팀 | D17: 김연호 | E17: 파트장 | F17: 정규 | G17: 0.72916667 | I17: 0.35416667 | J17: 0.72916667 | K17: =IF(OR(I17="",J17=""),0, IF(AND(HOUR(I17)=8,MINUTE(I17)=30), IF(IF(J17<I17,J17+1,J17)<TIME(18,0,0),0, IF(IF(J17<I17,J17+1,J17)<=TIME(19,30,0), ROUND((IF(J17<I17,J17+1,J17)-TIME(17,30,0))*24,1), ROUND((IF(J17<I17,J17+1,J17)-TIME(18,30,0))*24,1) ) ), IF(AND(HOUR(I17)=10,MINUTE(I17)=0), IF(IF(J17<I17,J17+1,J17)<=TIME(20,0,0),0, ROUND((IF(J17<I17,J17+1,J17)-TIME(20,0,0))*24,1) ), 0 ) )) -> 0 | L17: =IFERROR(VLOOKUP(K17,기준!F:G,2,FALSE),"") -> 0.72916667 | M17: =K17 -> 0 | N17: 휴무 | O17: 0.72916667 | Q17: 0 | R17: 신규 모델 관련 업무 진행 | S17: VINA 출장 | U17: 0.83333333 | V17: =COUNTIF($J$7:$J$19,U17) -> 0
B18: =+ROW()-6 -> 12 | C18: 제어파트 | D18: 김동련 | E18: 팀원 | F18: 정규 | G18: 0.72916667 | I18: 0.35416667 | J18: 0.72916667 | K18: =IF(OR(I18="",J18=""),0, IF(AND(HOUR(I18)=8,MINUTE(I18)=30), IF(IF(J18<I18,J18+1,J18)<TIME(18,0,0),0, IF(IF(J18<I18,J18+1,J18)<=TIME(19,30,0), ROUND((IF(J18<I18,J18+1,J18)-TIME(17,30,0))*24,1), ROUND((IF(J18<I18,J18+1,J18)-TIME(18,30,0))*24,1) ) ), IF(AND(HOUR(I18)=10,MINUTE(I18)=0), IF(IF(J18<I18,J18+1,J18)<=TIME(20,0,0),0, ROUND((IF(J18<I18,J18+1,J18)-TIME(20,0,0))*24,1) ), 0 ) )) -> 0 | L18: =IFERROR(VLOOKUP(K18,기준!F:G,2,FALSE),"") -> 0.72916667 | M18: =K18 -> 0 | N18: 휴무 | O18: 0.72916667 | Q18: 0 | R18: 신규 모델 관련 업무 진행 | U18: 0.875 | V18: =COUNTIF($J$7:$J$19,U18) -> 0
B19: =+ROW()-6 -> 13 | C19: 제어파트 | D19: 심효정 | E19: 팀원 | F19: 정규 | G19: 0.72916667 | I19: 0.35416667 | J19: 0.72916667 | K19: =IFERROR(VLOOKUP(J19,[1]기준!B:C,2,FALSE),"")-IFERROR(VLOOKUP(I19,[1]기준!D:E,2,FALSE),"") -> 0 | L19: =IFERROR(VLOOKUP(K19,기준!F:G,2,FALSE),"") -> 0.72916667 | M19: =K19 -> 0 | N19: 신규 모델 관련 업무 진행 | O19: 0.72916667 | Q19: 0 | R19: 휴무 | U19: 0.89583333 | V19: =COUNTIF($J$7:$J$19,U19) -> 0
B20: =+ROW()-6 -> 14 | C20: 개발1팀 | D20: 김연호 | E20: 파트장 | F20: 정규 | G20: 0.72916667 | I20: 0.35416667 | J20: 0.72916667 | K20: =IFERROR(VLOOKUP(J20,기준!B:C,2,FALSE),"")-IFERROR(VLOOKUP(I20,기준!D:E,2,FALSE),"") -> 0 | L20: =IFERROR(VLOOKUP(K20,기준!F:G,2,FALSE),"") -> 0.72916667 | M20: =K20 -> 0 | N20: 신규 모델 관련 업무 진행 | O20: 0.72916667 | Q20: 0 | R20: 휴무 | U20: 1 | V20: =COUNTIF($J$7:$J$19,U20) -> 0
B21: =+ROW()-6 -> 15 | C21: 제어파트 | D21: 김동련 | E21: 팀원 | F21: 정규 | G21: 0.72916667 | I21: 0.35416667 | J21: 0.72916667 | K21: =IFERROR(VLOOKUP(J21,기준!B:C,2,FALSE),"")-IFERROR(VLOOKUP(I21,기준!D:E,2,FALSE),"") -> 0 | L21: =IFERROR(VLOOKUP(K21,기준!F:G,2,FALSE),"") -> 0.72916667 | M21: =K21 -> 0 | N21: 신규 모델 관련 업무 진행 | O21: 0.72916667 | Q21: 0 | R21: 휴무 | U21: 1.0208333 | V21: =COUNTIF($J$7:$J$19,U21) -> 0
B22: =+ROW()-6 -> 16 | C22: 제어파트 | D22: 심효정 | E22: 팀원 | F22: 정규 | G22: 0.72916667 | I22: 0.35416667 | J22: 0.72916667 | K22: =IFERROR(VLOOKUP(J22,기준!B:C,2,FALSE),"")-IFERROR(VLOOKUP(I22,기준!D:E,2,FALSE),"") -> 0 | L22: =IFERROR(VLOOKUP(K22,기준!F:G,2,FALSE),"") -> 0.72916667 | M22: =K22 -> 0 | N22: 신규 모델 관련 업무 진행 | O22: 0.72916667 | Q22: 0 | R22: 휴무 | U22: 1.0416667 | V22: =COUNTIF($J$7:$J$19,U22) -> 0
B23: =+ROW()-6 -> 17 | C23: 제어파트 | D23: 심효정 | E23: 팀원 | F23: 정규 | G23: 0.72916667 | I23: 0.35416667 | J23: 0.72916667 | K23: =IFERROR(VLOOKUP(J23,기준!B:C,2,FALSE),"")-IFERROR(VLOOKUP(I23,기준!D:E,2,FALSE),"") -> 0 | L23: =IFERROR(VLOOKUP(K23,기준!F:G,2,FALSE),"") -> 0.72916667 | M23: =K23 -> 0 | N23: 신규 모델 관련 업무 진행 | O23: 0.72916667 | Q23: 0 | R23: 휴무 | U23: 1.0625 | V23: =COUNTIF($J$7:$J$19,U23) -> 0
B24: =+ROW()-6 -> 18 | C24: 제어파트 | D24: 심효정 | E24: 팀원 | F24: 정규 | G24: 0.72916667 | I24: 0.35416667 | J24: 0.72916667 | K24: =IFERROR(VLOOKUP(J24,기준!B:C,2,FALSE),"")-IFERROR(VLOOKUP(I24,기준!D:E,2,FALSE),"") -> 0 | L24: =IFERROR(VLOOKUP(K24,기준!F:G,2,FALSE),"") -> 0.72916667 | M24: =K24 -> 0 | N24: 신규 모델 관련 업무 진행 | O24: 0.72916667 | Q24: 0 | R24: 휴무 | U24: 1.0833333 | V24: =COUNTIF($J$7:$J$19,U24) -> 0
B25: =+ROW()-6 -> 19 | C25: 제어파트 | D25: 심효정 | E25: 팀원 | F25: 정규 | G25: 0.72916667 | I25: 0.35416667 | J25: 0.72916667 | K25: =IFERROR(VLOOKUP(J25,기준!B:C,2,FALSE),"")-IFERROR(VLOOKUP(I25,기준!D:E,2,FALSE),"") -> 0 | L25: =IFERROR(VLOOKUP(K25,기준!F:G,2,FALSE),"") -> 0.72916667 | M25: =K25 -> 0 | N25: 신규 모델 관련 업무 진행 | O25: 0.72916667 | Q25: 0 | R25: 휴무
B26: =+ROW()-6 -> 20 | C26: 제어파트 | D26: 심효정 | E26: 팀원 | F26: 정규 | G26: 0.72916667 | I26: 0.35416667 | J26: 0.72916667 | K26: =IFERROR(VLOOKUP(J26,기준!B:C,2,FALSE),"")-IFERROR(VLOOKUP(I26,기준!D:E,2,FALSE),"") -> 0 | L26: =IFERROR(VLOOKUP(K26,기준!F:G,2,FALSE),"") -> 0.72916667 | M26: =K26 -> 0 | N26: 신규 모델 관련 업무 진행 | O26: 0.72916667 | Q26: 0 | R26: 휴무
B27: =+ROW()-6 -> 21 | C27: 제어파트 | D27: 심효정 | E27: 팀원 | F27: 정규 | G27: 0.72916667 | I27: 0.35416667 | J27: 0.72916667 | K27: =IFERROR(VLOOKUP(J27,기준!B:C,2,FALSE),"")-IFERROR(VLOOKUP(I27,기준!D:E,2,FALSE),"") -> 0 | L27: =IFERROR(VLOOKUP(K27,기준!F:G,2,FALSE),"") -> 0.72916667 | M27: =K27 -> 0 | N27: 신규 모델 관련 업무 진행 | O27: 0.72916667 | Q27: 0 | R27: 휴무
B28: =+ROW()-6 -> 22 | C28: 제어파트 | D28: 심효정 | E28: 팀원 | F28: 정규 | G28: 0.72916667 | I28: 0.35416667 | J28: 0.72916667 | K28: =IFERROR(VLOOKUP(J28,기준!B:C,2,FALSE),"")-IFERROR(VLOOKUP(I28,기준!D:E,2,FALSE),"") -> 0 | L28: =IFERROR(VLOOKUP(K28,기준!F:G,2,FALSE),"") -> 0.72916667 | M28: =K28 -> 0 | N28: 신규 모델 관련 업무 진행 | O28: 0.72916667 | Q28: 0 | R28: 휴무
B29: =+ROW()-6 -> 23 | C29: 제어파트 | D29: 심효정 | E29: 팀원 | F29: 정규 | G29: 0.72916667 | I29: 0.35416667 | J29: 0.72916667 | K29: =IFERROR(VLOOKUP(J29,기준!B:C,2,FALSE),"")-IFERROR(VLOOKUP(I29,기준!D:E,2,FALSE),"") -> 0 | L29: =IFERROR(VLOOKUP(K29,기준!F:G,2,FALSE),"") -> 0.72916667 | M29: =K29 -> 0 | N29: 신규 모델 관련 업무 진행 | O29: 0.72916667 | Q29: 0 | R29: 휴무
B30: =+ROW()-6 -> 24 | C30: 제어파트 | D30: 심효정 | E30: 팀원 | F30: 정규 | G30: 0.72916667 | I30: 0.35416667 | J30: 0.72916667 | K30: =IFERROR(VLOOKUP(J30,기준!B:C,2,FALSE),"")-IFERROR(VLOOKUP(I30,기준!D:E,2,FALSE),"") -> 0 | L30: =IFERROR(VLOOKUP(K30,기준!F:G,2,FALSE),"") -> 0.72916667 | M30: =K30 -> 0 | N30: 신규 모델 관련 업무 진행 | O30: 0.72916667 | Q30: 0 | R30: 휴무
B31: =+ROW()-6 -> 25 | C31: 제어파트 | D31: 심효정 | E31: 팀원 | F31: 정규 | G31: 0.72916667 | I31: 0.35416667 | J31: 0.72916667 | K31: =IFERROR(VLOOKUP(J31,기준!B:C,2,FALSE),"")-IFERROR(VLOOKUP(I31,기준!D:E,2,FALSE),"") -> 0 | L31: =IFERROR(VLOOKUP(K31,기준!F:G,2,FALSE),"") -> 0.72916667 | M31: =K31 -> 0 | N31: 신규 모델 관련 업무 진행 | O31: 0.72916667 | Q31: 0 | R31: 휴무
B32: =+ROW()-6 -> 26 | C32: 제어파트 | D32: 심효정 | E32: 팀원 | F32: 정규 | G32: 0.72916667 | I32: 0.35416667 | J32: 0.72916667 | K32: =IFERROR(VLOOKUP(J32,기준!B:C,2,FALSE),"")-IFERROR(VLOOKUP(I32,기준!D:E,2,FALSE),"") -> 0 | L32: =IFERROR(VLOOKUP(K32,기준!F:G,2,FALSE),"") -> 0.72916667 | M32: =K32 -> 0 | N32: 신규 모델 관련 업무 진행 | O32: 0.72916667 | Q32: 0 | R32: 휴무
B33: =+ROW()-6 -> 27 | C33: 제어파트 | D33: 심효정 | E33: 팀원 | F33: 정규 | G33: 0.72916667 | I33: 0.35416667 | J33: 0.72916667 | K33: =IFERROR(VLOOKUP(J33,기준!B:C,2,FALSE),"")-IFERROR(VLOOKUP(I33,기준!D:E,2,FALSE),"") -> 0 | L33: =IFERROR(VLOOKUP(K33,기준!F:G,2,FALSE),"") -> 0.72916667 | M33: =K33 -> 0 | N33: 신규 모델 관련 업무 진행 | O33: 0.72916667 | Q33: 0 | R33: 휴무
B34: =+ROW()-6 -> 28 | C34: 제어파트 | D34: 심효정 | E34: 팀원 | F34: 정규 | G34: 0.72916667 | I34: 0.35416667 | J34: 0.72916667 | K34: =IFERROR(VLOOKUP(J34,기준!B:C,2,FALSE),"")-IFERROR(VLOOKUP(I34,기준!D:E,2,FALSE),"") -> 0 | L34: =IFERROR(VLOOKUP(K34,기준!F:G,2,FALSE),"") -> 0.72916667 | M34: =K34 -> 0 | N34: 신규 모델 관련 업무 진행 | O34: 0.72916667 | Q34: 0 | R34: 휴무
B35: =+ROW()-6 -> 29 | C35: 제어파트 | D35: 심효정 | E35: 팀원 | F35: 정규 | G35: 0.72916667 | I35: 0.35416667 | J35: 0.72916667 | K35: =IFERROR(VLOOKUP(J35,기준!B:C,2,FALSE),"")-IFERROR(VLOOKUP(I35,기준!D:E,2,FALSE),"") -> 0 | L35: =IFERROR(VLOOKUP(K35,기준!F:G,2,FALSE),"") -> 0.72916667 | M35: =K35 -> 0 | N35: 신규 모델 관련 업무 진행 | O35: 0.72916667 | Q35: 0 | R35: 휴무
B36: =+ROW()-6 -> 30 | C36: 제어파트 | D36: 심효정 | E36: 팀원 | F36: 정규 | G36: 0.72916667 | I36: 0.35416667 | J36: 0.72916667 | K36: =IFERROR(VLOOKUP(J36,기준!B:C,2,FALSE),"")-IFERROR(VLOOKUP(I36,기준!D:E,2,FALSE),"") -> 0 | L36: =IFERROR(VLOOKUP(K36,기준!F:G,2,FALSE),"") -> 0.72916667 | M36: =K36 -> 0 | N36: 신규 모델 관련 업무 진행 | O36: 0.72916667 | Q36: 0 | R36: 휴무
... B43: =+ROW()-6 -> 37 | C43: 제어파트 | D43: 심효정 | E43: 팀원 | F43: 정규 | G43: 0.72916667 | I43: 0.35416667 | J43: 0.72916667 | K43: =IFERROR(VLOOKUP(J43,기준!B:C,2,FALSE),"")-IFERROR(VLOOKUP(I43,기준!D:E,2,FALSE),"") -> 0 | L43: =IFERROR(VLOOKUP(K43,기준!F:G,2,FALSE),"") -> 0.72916667 | M43: =K43 -> 0 | N43: 신규 모델 관련 업무 진행 | O43: 0.72916667 | Q43: 0 | R43: 휴무

Sheet 평일
B2: 연장근무표_AF사업부
B3: 46104 | F3: 평일
B4: No | C4: 팀 | D4: 이름 | E4: 직위 | F4: 형태 | G4: 연장 근무 확정 | N4: =B3-1 -> 46103 | O4: 연장 근무 신청 | R4: =B3 -> 46104 | S4: 잔여 시간 | U4: 작성 확인
G5: 신청 | I5: 실제 | L5: 정상출근 기준 퇴근시간 | M5: 승인 | N5: 업무내용 | O5: 담당자 신청 | Q5: 승인 | R5: 업무내용
G6: 퇴근 | I6: 출근 | J6: 퇴근 | O6: 퇴근 | P6: 신청 | U6: 출/퇴근시간 | V6: 인원수
B7: =+ROW()-6 -> 1 | C7: 개발1팀 | D7: 임형준 | E7: 팀장 | F7: 정규 | G7: 0.72916667 | I7: 0.35416667 | J7: 0.72916667 | K7: =IF(OR(I7="",J7=""),0, IF(AND(HOUR(I7)=8,MINUTE(I7)=30), IF(IF(J7<I7,J7+1,J7)<TIME(18,0,0),0, IF(IF(J7<I7,J7+1,J7)<=TIME(19,30,0), ROUND((IF(J7<I7,J7+1,J7)-TIME(17,30,0))*24,1), ROUND((IF(J7<I7,J7+1,J7)-TIME(18,30,0))*24,1) ) ), IF(AND(HOUR(I7)=10,MINUTE(I7)=0), IF(IF(J7<I7,J7+1,J7)<=TIME(20,0,0),0, ROUND((IF(J7<I7,J7+1,J7)-TIME(20,0,0))*24,1) ), 0 ) )) -> 0 | L7: =IFERROR(VLOOKUP(K7,기준!F:G,2,FALSE),"") -> 0.72916667 | M7: =K7 -> 0 | N7: 휴무 | O7: 0.72916667 | Q7: 0 | R7: 신규 모델 관련 업무 진행 | S7: 휴무 | U7: 0.35416667 | V7: =COUNTIF($I$7:$I$19,U7) -> 13
B8: =+ROW()-6 -> 2 | C8: 개발2팀 | D8: 박정환 | E8: 팀원 | F8: 정규 | G8: 0.72916667 | I8: 0.35416667 | J8: 0.72916667 | K8: =IF(OR(I8="",J8=""),0, IF(AND(HOUR(I8)=8,MINUTE(I8)=30), IF(IF(J8<I8,J8+1,J8)<TIME(18,0,0),0, IF(IF(J8<I8,J8+1,J8)<=TIME(19,30,0), ROUND((IF(J8<I8,J8+1,J8)-TIME(17,30,0))*24,1), ROUND((IF(J8<I8,J8+1,J8)-TIME(18,30,0))*24,1) ) ), IF(AND(HOUR(I8)=10,MINUTE(I8)=0), IF(IF(J8<I8,J8+1,J8)<=TIME(20,0,0),0, ROUND((IF(J8<I8,J8+1,J8)-TIME(20,0,0))*24,1) ), 0 ) )) -> 0 | L8: =IFERROR(VLOOKUP(K8,기준!F:G,2,FALSE),"") -> 0.72916667 | M8: =K8 -> 0 | N8: 휴무 | O8: 0.72916667 | Q8: 0 | R8: 신규 모델 관련 업무 진행 | S8: 휴무 | U8: 0.39583333 | V8: =COUNTIF($I$7:$I$19,U8) -> 0
B9: =+ROW()-6 -> 3 | C9: 개발1팀 | D9: 박정찬 | E9: 팀원 | F9: 정규 | G9: 0.72916667 | I9: 0.35416667 | J9: 0.72916667 | K9: =IF(OR(I9="",J9=""),0, IF(AND(HOUR(I9)=8,MINUTE(I9)=30), IF(IF(J9<I9,J9+1,J9)<TIME(18,0,0),0, IF(IF(J9<I9,J9+1,J9)<=TIME(19,30,0), ROUND((IF(J9<I9,J9+1,J9)-TIME(17,30,0))*24,1), ROUND((IF(J9<I9,J9+1,J9)-TIME(18,30,0))*24,1) ) ), IF(AND(HOUR(I9)=10,MINUTE(I9)=0), IF(IF(J9<I9,J9+1,J9)<=TIME(20,0,0),0, ROUND((IF(J9<I9,J9+1,J9)-TIME(20,0,0))*24,1) ), 0 ) )) -> 0 | L9: =IFERROR(VLOOKUP(K9,기준!F:G,2,FALSE),"") -> 0.72916667 | M9: =K9 -> 0 | N9: 휴무 | O9: 0.72916667 | Q9: 0 | R9: 신규 모델 관련 업무 진행 | S9: VINA 출장 | U9: 0.41666667 | V9: =COUNTIF($I$7:$I$19,U9) -> 0
B10: =+ROW()-6 -> 4 | C10: 개발1팀 | D10: 박태준 | E10: 팀원 | F10: 정규 | G10: 0.72916667 | I10: 0.35416667 | J10: 0.72916667 | K10: =IF(OR(I10="",J10=""),0, IF(AND(HOUR(I10)=8,MINUTE(I10)=30), IF(IF(J10<I10,J10+1,J10)<TIME(18,0,0),0, IF(IF(J10<I10,J10+1,J10)<=TIME(19,30,0), ROUND((IF(J10<I10,J10+1,J10)-TIME(17,30,0))*24,1), ROUND((IF(J10<I10,J10+1,J10)-TIME(18,30,0))*24,1) ) ), IF(AND(HOUR(I10)=10,MINUTE(I10)=0), IF(IF(J10<I10,J10+1,J10)<=TIME(20,0,0),0, ROUND((IF(J10<I10,J10+1,J10)-TIME(20,0,0))*24,1) ), 0 ) )) -> 0 | L10: =IFERROR(VLOOKUP(K10,기준!F:G,2,FALSE),"") -> 0.72916667 | M10: =K10 -> 0 | N10: 휴무 | O10: 0.72916667 | Q10: 0 | R10: 신규 모델 관련 업무 진행 | U10: 0.5625 | V10: =COUNTIF($I$7:$I$19,U10) -> 0
B11: =+ROW()-6 -> 5 | C11: 개발1팀 | D11: 이형석 | E11: 팀원 | F11: 정규 | G11: 0.72916667 | I11: 0.35416667 | J11: 0.72916667 | K11: =IF(OR(I11="",J11=""),0, IF(AND(HOUR(I11)=8,MINUTE(I11)=30), IF(IF(J11<I11,J11+1,J11)<TIME(18,0,0),0, IF(IF(J11<I11,J11+1,J11)<=TIME(19,30,0), ROUND((IF(J11<I11,J11+1,J11)-TIME(17,30,0))*24,1), ROUND((IF(J11<I11,J11+1,J11)-TIME(18,30,0))*24,1) ) ), IF(AND(HOUR(I11)=10,MINUTE(I11)=0), IF(IF(J11<I11,J11+1,J11)<=TIME(20,0,0),0, ROUND((IF(J11<I11,J11+1,J11)-TIME(20,0,0))*24,1) ), 0 ) )) -> 0 | L11: =IFERROR(VLOOKUP(K11,기준!F:G,2,FALSE),"") -> 0.72916667 | M11: =K11 -> 0 | N11: 휴무 | O11: 0.72916667 | Q11: 0 | R11: 신규 모델 관련 업무 진행 | U11: 0.72916667 | V11: =COUNTIF($J$7:$J$19,U11) -> 13
B12: =+ROW()-6 -> 6 | C12: 개발1팀 | D12: 김준영 | E12: 팀원 | F12: 정규 | G12: 0.72916667 | I12: 0.35416667 | J12: 0.72916667 | K12: =IF(OR(I12="",J12=""),0, IF(AND(HOUR(I12)=8,MINUTE(I12)=30), IF(IF(J12<I12,J12+1,J12)<TIME(18,0,0),0, IF(IF(J12<I12,J12+1,J12)<=TIME(19,30,0), ROUND((IF(J12<I12,J12+1,J12)-TIME(17,30,0))*24,1), ROUND((IF(J12<I12,J12+1,J12)-TIME(18,30,0))*24,1) ) ), IF(AND(HOUR(I12)=10,MINUTE(I12)=0), IF(IF(J12<I12,J12+1,J12)<=TIME(20,0,0),0, ROUND((IF(J12<I12,J12+1,J12)-TIME(20,0,0))*24,1) ), 0 ) )) -> 0 | L12: =IFERROR(VLOOKUP(K12,기준!F:G,2,FALSE),"") -> 0.72916667 | M12: =K12 -> 0 | N12: 휴무 | O12: 0.72916667 | Q12: 0 | R12: 신규 모델 관련 업무 진행 | U12: 0.75 | V12: =COUNTIF($J$7:$J$19,U12) -> 0
B13: =+ROW()-6 -> 7 | C13: 개발1팀 | D13: 성민혁 | E13: 팀원 | F13: 정규 | G13: 0.72916667 | I13: 0.35416667 | J13: 0.72916667 | K13: =IF(OR(I13="",J13=""),0, IF(AND(HOUR(I13)=8,MINUTE(I13)=30), IF(IF(J13<I13,J13+1,J13)<TIME(18,0,0),0, IF(IF(J13<I13,J13+1,J13)<=TIME(19,30,0), ROUND((IF(J13<I13,J13+1,J13)-TIME(17,30,0))*24,1), ROUND((IF(J13<I13,J13+1,J13)-TIME(18,30,0))*24,1) ) ), IF(AND(HOUR(I13)=10,MINUTE(I13)=0), IF(IF(J13<I13,J13+1,J13)<=TIME(20,0,0),0, ROUND((IF(J13<I13,J13+1,J13)-TIME(20,0,0))*24,1) ), 0 ) )) -> 0 | L13: =IFERROR(VLOOKUP(K13,기준!F:G,2,FALSE),"") -> 0.72916667 | M13: =K13 -> 0 | N13: 휴무 | O13: 0.72916667 | Q13: 0 | R13: 신규 모델 관련 업무 진행 | U13: 0.77083333 | V13: =COUNTIF($J$7:$J$19,U13) -> 0
B14: =+ROW()-6 -> 8 | C14: 개발1팀 | D14: 김남훈 | E14: 팀원 | F14: 정규 | G14: 0.72916667 | I14: 0.35416667 | J14: 0.72916667 | K14: =IF(OR(I14="",J14=""),0, IF(AND(HOUR(I14)=8,MINUTE(I14)=30), IF(IF(J14<I14,J14+1,J14)<TIME(18,0,0),0, IF(IF(J14<I14,J14+1,J14)<=TIME(19,30,0), ROUND((IF(J14<I14,J14+1,J14)-TIME(17,30,0))*24,1), ROUND((IF(J14<I14,J14+1,J14)-TIME(18,30,0))*24,1) ) ), IF(AND(HOUR(I14)=10,MINUTE(I14)=0), IF(IF(J14<I14,J14+1,J14)<=TIME(20,0,0),0, ROUND((IF(J14<I14,J14+1,J14)-TIME(20,0,0))*24,1) ), 0 ) )) -> 0 | L14: =IFERROR(VLOOKUP(K14,기준!F:G,2,FALSE),"") -> 0.72916667 | M14: =K14 -> 0 | N14: 휴무 | O14: 0.72916667 | Q14: 0 | R14: 신규 모델 관련 업무 진행 | U14: 0.79166667 | V14: =COUNTIF($J$7:$J$19,U14) -> 0
B15: =+ROW()-6 -> 9 | C15: 개발2팀 | D15: 이종훈 | E15: 팀원 | F15: 정규 | G15: 0.72916667 | I15: 0.35416667 | J15: 0.72916667 | K15: =IF(OR(I15="",J15=""),0, IF(AND(HOUR(I15)=8,MINUTE(I15)=30), IF(IF(J15<I15,J15+1,J15)<TIME(18,0,0),0, IF(IF(J15<I15,J15+1,J15)<=TIME(19,30,0), ROUND((IF(J15<I15,J15+1,J15)-TIME(17,30,0))*24,1), ROUND((IF(J15<I15,J15+1,J15)-TIME(18,30,0))*24,1) ) ), IF(AND(HOUR(I15)=10,MINUTE(I15)=0), IF(IF(J15<I15,J15+1,J15)<=TIME(20,0,0),0, ROUND((IF(J15<I15,J15+1,J15)-TIME(20,0,0))*24,1) ), 0 ) )) -> 0 | L15: =IFERROR(VLOOKUP(K15,기준!F:G,2,FALSE),"") -> 0.72916667 | M15: =K15 -> 0 | N15: 휴무 | O15: 0.72916667 | Q15: 0 | R15: 신규 모델 관련 업무 진행
B16: =+ROW()-6 -> 10 | C16: 개발3팀 | D16: 강한울 | E16: 파트장 | F16: 정규 | G16: 0.72916667 | I16: 0.35416667 | J16: 0.72916667 | K16: =IF(OR(I16="",J16=""),0, IF(AND(HOUR(I16)=8,MINUTE(I16)=30), IF(IF(J16<I16,J16+1,J16)<TIME(18,0,0),0, IF(IF(J16<I16,J16+1,J16)<=TIME(19,30,0), ROUND((IF(J16<I16,J16+1,J16)-TIME(17,30,0))*24,1), ROUND((IF(J16<I16,J16+1,J16)-TIME(18,30,0))*24,1) ) ), IF(AND(HOUR(I16)=10,MINUTE(I16)=0), IF(IF(J16<I16,J16+1,J16)<=TIME(20,0,0),0, ROUND((IF(J16<I16,J16+1,J16)-TIME(20,0,0))*24,1) ), 0 ) )) -> 0 | L16: =IFERROR(VLOOKUP(K16,기준!F:G,2,FALSE),"") -> 0.72916667 | M16: =K16 -> 0 | N16: 휴무 | O16: 0.72916667 | Q16: 0 | R16: 신규 모델 관련 업무 진행 | S16: 휴무 | U16: 0.8125 | V16: =COUNTIF($J$7:$J$19,U16) -> 0
